Workbook
Name analisis: 'Analisis (10)'!$B$2:$E$10
Name daftarakun: 'Formula (2)'!$C$2:$H$146
Name filter: 'Ledger (4)'!$J$2
Name JB: 'Jurnal Umum (3)'!$L$7:$L$96
Name JK: 'Jurnal Umum (3)'!$M$7:$M$96
Name JP: #REF!
Name JU: 'Jurnal Umum (3)'!$D:$M
Name Jurnal: 'Jurnal Umum (3)'!$G:$M
Name kbju: 'Jurnal Umum (3)'!$D:$E
Name KBNS: 'Jurnal Umum (3)'!$B$7:$B$149
Name KBPNY: 'Jurnal Umum (3)'!$C$7:$C$149
Name kode: 'Formula (2)'!$C$7:$C$285
Name lap_lr: #REF!
Name neracalajur: 'Worksheet (6)'!$B:$S
Name perubahanmodal: 'Changes Capital Statement (9)'!$B:$G

Sheet Menu (0)

Sheet HPP
B3: PBD A | E3: 0
B5: Pembelian | D5: 118000000
B6: Beban angkut pembelian | D6: 0
B8: Total pembelian | C8: Ʃ | D8: =SUM(D5:D6) -> 118000000 | E8: =E3 -> 0
B10: Retur pembelian | D10: 0
B11: Potongan pembelian | D11: 2010000
B12: Total Potongan pembelian | D12: =SUM(D10:D11) -> 2010000
B14: Total Pembelian bersih | C14: Ʃ | D14: =D8-D12 -> 115990000 | E14: =SUM(E10:E12) -> 0
B16: Barang yang tersediaan | D16: 0
B18: PBD B | D18: 127000000
B20: HPP | D20: =D14-D16-D18 -> -11010000

Sheet Transaksi (1)
B2: Mazmur Larosa Production
B3: Transaksi
B4: Periode Desember 2021
B5: ~ Dilarang keras merubah (Apapun) yang bukan menjadi kepentingan Anda ! ~

Sheet Formula (2)
C2: ='Transaksi (1)'!B2:E2 -> 0
C3: Daftar Akun Siklus & saldo awal | L3: Pin
C4: ='Transaksi (1)'!B4:E4 -> 0
C5: Kode | D5: Nama Akun | E5: Pos | F5: SN | G5: Saldo Awal
B6: KK | G6: Debit | H6: Kredit
B7: =IF(D7="",0,1) -> 1 | C7: 10000 | D7: Harta Lancar | E7: Nrc | F7: Db
B8: =IF(D8="",0,1) -> 1 | C8: 10001 | D8: Kas | E8: Nrc | F8: Db | G8: 100000
B9: =IF(D9="",0,1) -> 1 | C9: 10002 | D9: Persediaan Barang Dagang | E9: Nrc | F9: Db
B10: =IF(D10="",0,1) -> 1 | C10: 10003 | D10: Piutang Usaha | E10: Nrc | F10: Db | G10: 500000
B11: =IF(D11="",0,1) -> 1 | C11: 10004 | D11: Piutang Pendapatan | E11: Nrc | F11: Db
B12: =IF(D12="",0,1) -> 1 | C12: 10005 | D12: Wesel Tagih | E12: Nrc | F12: Db
B13: =IF(D13="",0,1) -> 1 | C13: 10006 | D13: Perlengkapan Kantor | E13: Nrc | F13: Db
B14: =IF(D14="",0,1) -> 1 | C14: 10007 | D14: Perlengkapan Toko | E14: Nrc | F14: Db
B15: =IF(D15="",0,1) -> 1 | C15: 10008 | D15: Iklan Dibayar Dimuka | E15: Nrc | F15: Db
B16: =IF(D16="",0,1) -> 1 | C16: 10009 | D16: Sewa Dibayar Dimuka | E16: Nrc | F16: Db
B17: =IF(D17="",0,1) -> 1 | C17: 10010 | D17: Asuransi Dibayar Dimuka | E17: Nrc | F17: Db
B18: =IF(D18="",0,1) -> 0 | C18: 10011 | E18: Nrc | F18: Db
B19: =IF(D19="",0,1) -> 0 | C19: 10012 | E19: Nrc | F19: Db
B20: =IF(D20="",0,1) -> 0 | C20: 10013 | E20: Nrc | F20: Db
B21: =IF(D21="",0,1) -> 0 | C21: 10014 | E21: Nrc | F21: Db
B22: =IF(D22="",0,1) -> 0 | C22: 10015 | E22: Nrc | F22: Db
B23: =IF(D23="",0,1) -> 0 | C23: 10016 | E23: Nrc | F23: Db
B24: =IF(D24="",0,1) -> 0 | C24: 10017 | E24: Nrc | F24: Db
B25: =IF(D25="",0,1) -> 0 | C25: 10018 | E25: Nrc | F25: Db
B26: =IF(D26="",0,1) -> 0 | C26: 10019 | E26: Nrc | F26: Db
B27: =IF(D27="",0,1) -> 0 | C27: 10020 | E27: Nrc | F27: Db
B28: =IF(D28="",0,1) -> 1 | C28: 11000 | D28: Harta tetap | E28: Nrc | F28: Db
B29: =IF(D29="",0,1) -> 1 | C29: 11001 | D29: Peralatan Kantor | E29: Nrc | F29: Db
B30: =IF(D30="",0,1) -> 1 | C30: 11002 | D30: Akumulasi Penyusutan Peralatan Kantor | E30: Nrc | F30: Kr
B31: =IF(D31="",0,1) -> 1 | C31: 11003 | D31: Kendaraan | E31: Nrc | F31: Db
B32: =IF(D32="",0,1) -> 1 | C32: 11004 | D32: Akumulasi Penyusutan Peralatanan Kendaraan | E32: Nrc | F32: Kr
B33: =IF(D33="",0,1) -> 1 | C33: 11005 | D33: Gedung | E33: Nrc | F33: Db
B34: =IF(D34="",0,1) -> 1 | C34: 11006 | D34: Akumulasi Penyusutan Gedung | E34: Nrc | F34: Kr
B35: =IF(D35="",0,1) -> 1 | C35: 11007 | D35: Mesin | E35: Nrc | F35: Db
B36: =IF(D36="",0,1) -> 1 | C36: 11008 | D36: Akumulasi Penyusutan Mesin | E36: Nrc | F36: Kr
B37: =IF(D37="",0,1) -> 1 | C37: 11009 | D37: Peralatan Toko | E37: Nrc | F37: Db
B38: =IF(D38="",0,1) -> 1 | C38: 11010 | D38: Akumulasi Penyusutan Peralatan Toko | E38: Nrc | F38: Kr
B39: =IF(D39="",0,1) -> 1 | C39: 11011 | D39: Tanah | E39: Nrc | F39: Db
B40: =IF(D40="",0,1) -> 0 | C40: 11012 | E40: Nrc | F40: Db
B41: =IF(D41="",0,1) -> 0 | C41: 11013 | E41: Nrc | F41: Db
...

Sheet Jurnal Umum (3)
G2: CV Max Picture
G3: Jurnal Umum
G4: Periode Oktober 2020
G5: ~ Dilarang keras merubah (Apapun) yang bukan menjadi kepentingan Anda ! ~
B6: KBNS | C6: KBPNY | D6: KB2 | E6: KB | G6: Tanggal | H6: Ref | I6: Keterangan | J6: Kode | K6: Nama Akun | L6: Debit | M6: Kredit
B7: =IF(C7<>"","",J7) -> 10006 | C7: =IF(LEFT(H7,3)="AP-",J7,"") | D7: =IF(OR(E7=0,E7=""),"",COUNTIF($E$7:E7,E7)&E7) | E7: =IF(J7=filter,J7,"") | G7: 38718 | H7: JU-1 | I7: Beli Lem | J7: 10006 | K7: =IFERROR(IF(J7="","",VLOOKUP(J7,daftarakun,2,0)),"Masukan kode yang benar!") -> Perlengkapan Kantor | L7: 20000
B8: =IF(C8<>"","",J8) -> 10001 | C8: =IF(LEFT(H8,3)="AP-",J8,"") | D8: =IF(OR(E8=0,E8=""),"",COUNTIF($E$7:E8,E8)&E8) | E8: =IF(J8=filter,J8,"") | H8: JU-1 | I8: Beli Lem | J8: 10001 | K8: =IF(J8="","",VLOOKUP(J8,daftarakun,2,0)) -> Kas | M8: 20000
B9: =IF(C9<>"","",J9) -> 0 | C9: =IF(LEFT(H9,3)="AP-",J9,"") | D9: =IF(OR(E9=0,E9=""),"",COUNTIF($E$7:E9,E9)&E9) | E9: =IF(J9=filter,J9,"") | K9: =IF(J9="","",VLOOKUP(J9,daftarakun,2,0))
B10: =IF(C10<>"","",J10) | C10: =IF(LEFT(H10,3)="AP-",J10,"") -> 50006 | D10: =IF(OR(E10=0,E10=""),"",COUNTIF($E$7:E10,E10)&E10) -> 150006 | E10: =IF(J10=filter,J10,"") -> 50006 | H10: AP-1 | I10: Penyusutan Lem | J10: 50006 | K10: =IF(J10="","",VLOOKUP(J10,daftarakun,2,0)) -> Beban Perlengkapan Kantor | L10: 10000
B11: =IF(C11<>"","",J11) | C11: =IF(LEFT(H11,3)="AP-",J11,"") -> 10006 | D11: =IF(OR(E11=0,E11=""),"",COUNTIF($E$7:E11,E11)&E11) | E11: =IF(J11=filter,J11,"") | H11: AP-1 | I11: Penyusutan Lem | J11: 10006 | K11: =IF(J11="","",VLOOKUP(J11,daftarakun,2,0)) -> Perlengkapan Kantor | M11: 10000
B12: =IF(C12<>"","",J12) -> 0 | C12: =IF(LEFT(H12,3)="AP-",J12,"") | D12: =IF(OR(E12=0,E12=""),"",COUNTIF($E$7:E12,E12)&E12) | E12: =IF(J12=filter,J12,"") | K12: =IF(J12="","",VLOOKUP(J12,daftarakun,2,0))
B13: =IF(C13<>"","",J13) -> 0 | C13: =IF(LEFT(H13,3)="AP-",J13,"") | D13: =IF(OR(E13=0,E13=""),"",COUNTIF($E$7:E13,E13)&E13) | E13: =IF(J13=filter,J13,"") | K13: =IF(J13="","",VLOOKUP(J13,daftarakun,2,0))
B14: =IF(C14<>"","",J14) -> 0 | C14: =IF(LEFT(H14,3)="AP-",J14,"") | D14: =IF(OR(E14=0,E14=""),"",COUNTIF($E$7:E14,E14)&E14) | E14: =IF(J14=filter,J14,"") | K14: =IF(J14="","",VLOOKUP(J14,daftarakun,2,0))
B15: =IF(C15<>"","",J15) -> 0 | C15: =IF(LEFT(H15,3)="AP-",J15,"") | D15: =IF(OR(E15=0,E15=""),"",COUNTIF($E$7:E15,E15)&E15) | E15: =IF(J15=filter,J15,"") | K15: =IF(J15="","",VLOOKUP(J15,daftarakun,2,0))
B16: =IF(C16<>"","",J16) -> 0 | C16: =IF(LEFT(H16,3)="AP-",J16,"") | D16: =IF(OR(E16=0,E16=""),"",COUNTIF($E$7:E16,E16)&E16) | E16: =IF(J16=filter,J16,"") | K16: =IF(J16="","",VLOOKUP(J16,daftarakun,2,0))
B17: =IF(C17<>"","",J17) -> 0 | C17: =IF(LEFT(H17,3)="AP-",J17,"") | D17: =IF(OR(E17=0,E17=""),"",COUNTIF($E$7:E17,E17)&E17) | E17: =IF(J17=filter,J17,"") | K17: =IF(J17="","",VLOOKUP(J17,daftarakun,2,0))
B18: =IF(C18<>"","",J18) -> 0 | C18: =IF(LEFT(H18,3)="AP-",J18,"") | D18: =IF(OR(E18=0,E18=""),"",COUNTIF($E$7:E18,E18)&E18) | E18: =IF(J18=filter,J18,"") | K18: =IF(J18="","",VLOOKUP(J18,daftarakun,2,0))
B19: =IF(C19<>"","",J19) -> 0 | C19: =IF(LEFT(H19,3)="AP-",J19,"") | D19: =IF(OR(E19=0,E19=""),"",COUNTIF($E$7:E19,E19)&E19) | E19: =IF(J19=filter,J19,"") | K19: =IF(J19="","",VLOOKUP(J19,daftarakun,2,0))
B20: =IF(C20<>"","",J20) -> 0 | C20: =IF(LEFT(H20,3)="AP-",J20,"") | D20: =IF(OR(E20=0,E20=""),"",COUNTIF($E$7:E20,E20)&E20) | E20: =IF(J20=filter,J20,"") | K20: =IF(J20="","",VLOOKUP(J20,daftarakun,2,0))
B21: =IF(C21<>"","",J21) -> 0 | C21: =IF(LEFT(H21,3)="AP-",J21,"") | D21: =IF(OR(E21=0,E21=""),"",COUNTIF($E$7:E21,E21)&E21) | E21: =IF(J21=filter,J21,"") | K21: =IF(J21="","",VLOOKUP(J21,daftarakun,2,0))
B22: =IF(C22<>"","",J22) -> 0 | C22: =IF(LEFT(H22,3)="AP-",J22,"") | D22: =IF(OR(E22=0,E22=""),"",COUNTIF($E$7:E22,E22)&E22) | E22: =IF(J22=filter,J22,"") | K22: =IF(J22="","",VLOOKUP(J22,daftarakun,2,0))
B23: =IF(C23<>"","",J23) -> 0 | C23: =IF(LEFT(H23,3)="AP-",J23,"") | D23: =IF(OR(E23=0,E23=""),"",COUNTIF($E$7:E23,E23)&E23) | E23: =IF(J23=filter,J23,"") | K23: =IF(J23="","",VLOOKUP(J23,daftarakun,2,0))
... B33: =IF(C33<>"","",J33) -> 0 | C33: =IF(LEFT(H33,3)="AP-",J33,"") | D33: =IF(OR(E33=0,E33=""),"",COUNTIF($E$7:E33,E33)&E33) | E33: =IF(J33=filter,J33,"") | K33: =IF(J33="","",VLOOKUP(J33,daftarakun,2,0))
B34: =IF(C34<>"","",J34) -> 0 | C34: =IF(LEFT(H34,3)="AP-",J34,"") | D34: =IF(OR(E34=0,E34=""),"",COUNTIF($E$7:E34,E34)&E34) | E34: =IF(J34=filter,J34,"")
B35: =IF(C35<>"","",J35) -> 0 | C35: =IF(LEFT(H35,3)="AP-",J35,"") | D35: =IF(OR(E35=0,E35=""),"",COUNTIF($E$7:E35,E35)&E35) | E35: =IF(J35=filter,J35,"") | K35: =IF(J35="","",VLOOKUP(J35,daftarakun,2,0))
B36: =IF(C36<>"","",J36) -> 0 | C36: =IF(LEFT(H36,3)="AP-",J36,"") | D36: =IF(OR(E36=0,E36=""),"",COUNTIF($E$7:E36,E36)&E36) | E36: =IF(J36=filter,J36,"") | K36: =IF(J36="","",VLOOKUP(J36,daftarakun,2,0))
B37: =IF(C37<>"","",J37) -> 0 | C37: =IF(LEFT(H37,3)="AP-",J37,"") | D37: =IF(OR(E37=0,E37=""),"",COUNTIF($E$7:E37,E37)&E37) | E37: =IF(J37=filter,J37,"") | K37: =IF(J37="","",VLOOKUP(J37,daftarakun,2,0))
B38: =IF(C38<>"","",J38) -> 0 | C38: =IF(LEFT(H38,3)="AP-",J38,"") | D38: =IF(OR(E38=0,E38=""),"",COUNTIF($E$7:E38,E38)&E38) | E38: =IF(J38=filter,J38,"") | K38: =IF(J38="","",VLOOKUP(J38,daftarakun,2,0))
B39: =IF(C39<>"","",J39) -> 0 | C39: =IF(LEFT(H39,3)="AP-",J39,"") | D39: =IF(OR(E39=0,E39=""),"",COUNTIF($E$7:E39,E39)&E39) | E39: =IF(J39=filter,J39,"") | K39: =IF(J39="","",VLOOKUP(J39,daftarakun,2,0))
B40: =IF(C40<>"","",J40) -> 0 | C40: =IF(LEFT(H40,3)="AP-",J40,"") | D40: =IF(OR(E40=0,E40=""),"",COUNTIF($E$7:E40,E40)&E40) | E40: =IF(J40=filter,J40,"") | K40: =IF(J40="","",VLOOKUP(J40,daftarakun,2,0))
B41: =IF(C41<>"","",J41) -> 0 | C41: =IF(LEFT(H41,3)="AP-",J41,"") | D41: =IF(OR(E41=0,E41=""),"",COUNTIF($E$7:E41,E41)&E41) | E41: =IF(J41=filter,J41,"") | K41: =IF(J41="","",VLOOKUP(J41,daftarakun,2,0))
B42: =IF(C42<>"","",J42) -> 0 | C42: =IF(LEFT(H42,3)="AP-",J42,"") | D42: =IF(OR(E42=0,E42=""),"",COUNTIF($E$7:E42,E42)&E42) | E42: =IF(J42=filter,J42,"") | K42: =IF(J42="","",VLOOKUP(J42,daftarakun,2,0))
B43: =IF(C43<>"","",J43) -> 0 | C43: =IF(LEFT(H43,3)="AP-",J43,"") | D43: =IF(OR(E43=0,E43=""),"",COUNTIF($E$7:E43,E43)&E43) | E43: =IF(J43=filter,J43,"") | K43: =IF(J43="","",VLOOKUP(J43,daftarakun,2,0))
B44: =IF(C44<>"","",J44) -> 0 | C44: =IF(LEFT(H44,3)="AP-",J44,"") | D44: =IF(OR(E44=0,E44=""),"",COUNTIF($E$7:E44,E44)&E44) | E44: =IF(J44=filter,J44,"") | K44: =IF(J44="","",VLOOKUP(J44,daftarakun,2,0))
B45: =IF(C45<>"","",J45) -> 0 | C45: =IF(LEFT(H45,3)="AP-",J45,"") | D45: =IF(OR(E45=0,E45=""),"",COUNTIF($E$7:E45,E45)&E45) | E45: =IF(J45=filter,J45,"") | K45: =IF(J45="","",VLOOKUP(J45,daftarakun,2,0))
B46: =IF(C46<>"","",J46) -> 0 | C46: =IF(LEFT(H46,3)="AP-",J46,"") | D46: =IF(OR(E46=0,E46=""),"",COUNTIF($E$7:E46,E46)&E46) | E46: =IF(J46=filter,J46,"") | K46: =IF(J46="","",VLOOKUP(J46,daftarakun,2,0))
... B94: =IF(C94<>"","",J94) -> 0 | C94: =IF(LEFT(H94,3)="AP-",J94,"") | D94: =IF(OR(E94=0,E94=""),"",COUNTIF($E$7:E94,E94)&E94) | E94: =IF(J94=filter,J94,"") | K94: =IF(J94="","",VLOOKUP(J94,daftarakun,2,0))
B95: =IF(C95<>"","",J95) -> 0 | C95: =IF(LEFT(H95,3)="AP-",J95,"") | D95: =IF(OR(E95=0,E95=""),"",COUNTIF($E$7:E95,E95)&E95) | E95: =IF(J95=filter,J95,"") | K95: =IF(L95=M95,"Balance","Not Balance") -> Balance | L95: =SUM(L7:L94) -> 30000 | M95: =SUM(M7:M94) -> 30000

Sheet Ledger (4)
D2: ='Jurnal Umum (3)'!G2 -> CV Max Picture | I2: Pilih Akun | J2: 50006
D3: Buku Besar | I3: SN | J3: =VLOOKUP(filter,daftarakun,4,0) -> Db
D4: =IF(filter="","Pilih Akun!",VLOOKUP(filter,daftarakun,2,0)) -> Beban Perlengkapan Kantor | I4: Saldo awal
D5: Periode Desember 2021 | I5: =VLOOKUP(filter,daftarakun,5,0) -> 0 | J5: =VLOOKUP(filter,daftarakun,6,0) -> 0
D6: ='Trial Balance Ledger (5)'!C5 -> 0
B7: Filter | D7: No | E7: Tanggal | F7: Ref | G7: Keterangan | H7: Debit | I7: Kredit | J7: Saldo
B8: 1 | G8: Saldo awal
B9: =IF(J9="",0,1) -> 1 | D9: 1 | E9: =IFERROR(IF(filter="","",VLOOKUP(D9&filter,'Jurnal Umum (3)'!$D:$M,4,0)),"") -> 0 | F9: =IF(E9="","",VLOOKUP(D9&filter,'Jurnal Umum (3)'!$D:$M,5,0)) -> AP-1 | G9: =IF(E9="","",VLOOKUP(D9&filter,'Jurnal Umum (3)'!$D:$M,6,0)) -> Penyusutan Lem | H9: =IF(E9="",0,VLOOKUP(D9&filter,'Jurnal Umum (3)'!$D:$M,9,0)) -> 10000 | I9: =IF(E9="","",VLOOKUP(D9&filter,'Jurnal Umum (3)'!$D:$M,10,0)) -> 0 | J9: =IFERROR(IF($J$3="Db",J8+H9-I9,J8+I9-H9),"") -> 10000
B10: =IF(J10="",0,1) -> 0 | D10: 2 | E10: =IFERROR(IF(filter="","",VLOOKUP(D10&filter,'Jurnal Umum (3)'!$D:$M,4,0)),"") | F10: =IF(E10="","",VLOOKUP(D10&filter,'Jurnal Umum (3)'!$D:$M,5,0)) | G10: =IF(E10="","",VLOOKUP(D10&filter,'Jurnal Umum (3)'!$D:$M,6,0)) | H10: =IF(E10="",0,VLOOKUP(D10&filter,'Jurnal Umum (3)'!$D:$M,9,0)) -> 0 | I10: =IF(E10="","",VLOOKUP(D10&filter,'Jurnal Umum (3)'!$D:$M,10,0)) | J10: =IFERROR(IF($J$3="Db",J9+H10-I10,J9+I10-H10),"")
B11: =IF(J11="",0,1) -> 0 | D11: 3 | E11: =IFERROR(IF(filter="","",VLOOKUP(D11&filter,'Jurnal Umum (3)'!$D:$M,4,0)),"") | F11: =IF(E11="","",VLOOKUP(D11&filter,'Jurnal Umum (3)'!$D:$M,5,0)) | G11: =IF(E11="","",VLOOKUP(D11&filter,'Jurnal Umum (3)'!$D:$M,6,0)) | H11: =IF(E11="",0,VLOOKUP(D11&filter,'Jurnal Umum (3)'!$D:$M,9,0)) -> 0 | I11: =IF(E11="","",VLOOKUP(D11&filter,'Jurnal Umum (3)'!$D:$M,10,0)) | J11: =IFERROR(IF($J$3="Db",J10+H11-I11,J10+I11-H11),"")
B12: =IF(J12="",0,1) -> 0 | D12: 4 | E12: =IFERROR(IF(filter="","",VLOOKUP(D12&filter,'Jurnal Umum (3)'!$D:$M,4,0)),"") | F12: =IF(E12="","",VLOOKUP(D12&filter,'Jurnal Umum (3)'!$D:$M,5,0)) | G12: =IF(E12="","",VLOOKUP(D12&filter,'Jurnal Umum (3)'!$D:$M,6,0)) | H12: =IF(E12="",0,VLOOKUP(D12&filter,'Jurnal Umum (3)'!$D:$M,9,0)) -> 0 | I12: =IF(E12="","",VLOOKUP(D12&filter,'Jurnal Umum (3)'!$D:$M,10,0)) | J12: =IFERROR(IF($J$3="Db",J11+H12-I12,J11+I12-H12),"")
B13: =IF(J13="",0,1) -> 0 | D13: 5 | E13: =IFERROR(IF(filter="","",VLOOKUP(D13&filter,'Jurnal Umum (3)'!$D:$M,4,0)),"") | F13: =IF(E13="","",VLOOKUP(D13&filter,'Jurnal Umum (3)'!$D:$M,5,0)) | G13: =IF(E13="","",VLOOKUP(D13&filter,'Jurnal Umum (3)'!$D:$M,6,0)) | H13: =IF(E13="",0,VLOOKUP(D13&filter,'Jurnal Umum (3)'!$D:$M,9,0)) -> 0 | I13: =IF(E13="","",VLOOKUP(D13&filter,'Jurnal Umum (3)'!$D:$M,10,0)) | J13: =IFERROR(IF($J$3="Db",J12+H13-I13,J12+I13-H13),"")
B14: =IF(J14="",0,1) -> 0 | D14: 6 | E14: =IFERROR(IF(filter="","",VLOOKUP(D14&filter,'Jurnal Umum (3)'!$D:$M,4,0)),"") | F14: =IF(E14="","",VLOOKUP(D14&filter,'Jurnal Umum (3)'!$D:$M,5,0)) | G14: =IF(E14="","",VLOOKUP(D14&filter,'Jurnal Umum (3)'!$D:$M,6,0)) | H14: =IF(E14="",0,VLOOKUP(D14&filter,'Jurnal Umum (3)'!$D:$M,9,0)) -> 0 | I14: =IF(E14="","",VLOOKUP(D14&filter,'Jurnal Umum (3)'!$D:$M,10,0)) | J14: =IFERROR(IF($J$3="Db",J13+H14-I14,J13+I14-H14),"")
B15: =IF(J15="",0,1) -> 0 | D15: 7 | E15: =IFERROR(IF(filter="","",VLOOKUP(D15&filter,'Jurnal Umum (3)'!$D:$M,4,0)),"") | F15: =IF(E15="","",VLOOKUP(D15&filter,'Jurnal Umum (3)'!$D:$M,5,0)) | G15: =IF(E15="","",VLOOKUP(D15&filter,'Jurnal Umum (3)'!$D:$M,6,0)) | H15: =IF(E15="",0,VLOOKUP(D15&filter,'Jurnal Umum (3)'!$D:$M,9,0)) -> 0 | I15: =IF(E15="","",VLOOKUP(D15&filter,'Jurnal Umum (3)'!$D:$M,10,0)) | J15: =IFERROR(IF($J$3="Db",J14+H15-I15,J14+I15-H15),"")
B16: =IF(J16="",0,1) -> 0 | D16: 8 | E16: =IFERROR(IF(filter="","",VLOOKUP(D16&filter,'Jurnal Umum (3)'!$D:$M,4,0)),"") | F16: =IF(E16="","",VLOOKUP(D16&filter,'Jurnal Umum (3)'!$D:$M,5,0)) | G16: =IF(E16="","",VLOOKUP(D16&filter,'Jurnal Umum (3)'!$D:$M,6,0)) | H16: =IF(E16="",0,VLOOKUP(D16&filter,'Jurnal Umum (3)'!$D:$M,9,0)) -> 0 | I16: =IF(E16="","",VLOOKUP(D16&filter,'Jurnal Umum (3)'!$D:$M,10,0)) | J16: =IFERROR(IF($J$3="Db",J15+H16-I16,J15+I16-H16),"")
B17: =IF(J17="",0,1) -> 0 | D17: 9 | E17: =IFERROR(IF(filter="","",VLOOKUP(D17&filter,'Jurnal Umum (3)'!$D:$M,4,0)),"") | F17: =IF(E17="","",VLOOKUP(D17&filter,'Jurnal Umum (3)'!$D:$M,5,0)) | G17: =IF(E17="","",VLOOKUP(D17&filter,'Jurnal Umum (3)'!$D:$M,6,0)) | H17: =IF(E17="",0,VLOOKUP(D17&filter,'Jurnal Umum (3)'!$D:$M,9,0)) -> 0 | I17: =IF(E17="","",VLOOKUP(D17&filter,'Jurnal Umum (3)'!$D:$M,10,0)) | J17: =IFERROR(IF($J$3="Db",J16+H17-I17,J16+I17-H17),"")
B18: =IF(J18="",0,1) -> 0 | D18: 10 | E18: =IFERROR(IF(filter="","",VLOOKUP(D18&filter,'Jurnal Umum (3)'!$D:$M,4,0)),"") | F18: =IF(E18="","",VLOOKUP(D18&filter,'Jurnal Umum (3)'!$D:$M,5,0)) | G18: =IF(E18="","",VLOOKUP(D18&filter,'Jurnal Umum (3)'!$D:$M,6,0)) | H18: =IF(E18="",0,VLOOKUP(D18&filter,'Jurnal Umum (3)'!$D:$M,9,0)) -> 0 | I18: =IF(E18="","",VLOOKUP(D18&filter,'Jurnal Umum (3)'!$D:$M,10,0)) | J18: =IFERROR(IF($J$3="Db",J17+H18-I18,J17+I18-H18),"")
B19: =IF(J19="",0,1) -> 0 | D19: 11 | E19: =IFERROR(IF(filter="","",VLOOKUP(D19&filter,'Jurnal Umum (3)'!$D:$M,4,0)),"") | F19: =IF(E19="","",VLOOKUP(D19&filter,'Jurnal Umum (3)'!$D:$M,5,0)) | G19: =IF(E19="","",VLOOKUP(D19&filter,'Jurnal Umum (3)'!$D:$M,6,0)) | H19: =IF(E19="",0,VLOOKUP(D19&filter,'Jurnal Umum (3)'!$D:$M,9,0)) -> 0 | I19: =IF(E19="","",VLOOKUP(D19&filter,'Jurnal Umum (3)'!$D:$M,10,0)) | J19: =IFERROR(IF($J$3="Db",J18+H19-I19,J18+I19-H19),"")
B20: =IF(J20="",0,1) -> 0 | D20: 12 | E20: =IFERROR(IF(filter="","",VLOOKUP(D20&filter,'Jurnal Umum (3)'!$D:$M,4,0)),"") | F20: =IF(E20="","",VLOOKUP(D20&filter,'Jurnal Umum (3)'!$D:$M,5,0)) | G20: =IF(E20="","",VLOOKUP(D20&filter,'Jurnal Umum (3)'!$D:$M,6,0)) | H20: =IF(E20="",0,VLOOKUP(D20&filter,'Jurnal Umum (3)'!$D:$M,9,0)) -> 0 | I20: =IF(E20="","",VLOOKUP(D20&filter,'Jurnal Umum (3)'!$D:$M,10,0)) | J20: =IFERROR(IF($J$3="Db",J19+H20-I20,J19+I20-H20),"")
... B38: =IF(J38="",0,1) -> 0 | D38: 30 | E38: =IFERROR(IF(filter="","",VLOOKUP(D38&filter,'Jurnal Umum (3)'!$D:$M,4,0)),"") | F38: =IF(E38="","",VLOOKUP(D38&filter,'Jurnal Umum (3)'!$D:$M,5,0)) | G38: =IF(E38="","",VLOOKUP(D38&filter,'Jurnal Umum (3)'!$D:$M,6,0)) | H38: =IF(E38="",0,VLOOKUP(D38&filter,'Jurnal Umum (3)'!$D:$M,9,0)) -> 0 | I38: =IF(E38="","",VLOOKUP(D38&filter,'Jurnal Umum (3)'!$D:$M,10,0)) | J38: =IFERROR(IF($J$3="Db",J37+H38-I38,J37+I38-H38),"")
H39: =SUM(H8:H38) -> 10000 | I39: =SUM(I8:I38) -> 0

Sheet Trial Balance Ledger (5)
C3: Neraca Setelah Buku Besar
C4: ='Worksheet (6)'!B4:S4 -> 0
C5: ='Worksheet (6)'!B5:S5 -> 0
C6: Kode | D6: Nama Akun | E6: SN | F6: Pos | G6: Saldo awal | I6: Neraca Saldo | K6: Neraca saldo
G7: Debit | H7: Kredit | I7: Debit | J7: Kredit | K7: Debit | L7: Kredit
B8: =IF(D8=0,0,1) -> 1 | C8: ='Formula (2)'!C7 -> 10000 | D8: =IF(C8="","",VLOOKUP(C8,daftarakun,2,0)) -> Harta Lancar | E8: =IF(C8="","",VLOOKUP(C8,daftarakun,4,0)) -> Db | F8: =IF(C8="","",VLOOKUP(C8,daftarakun,3,0)) -> Nrc | G8: =IF(C8="","",VLOOKUP(C8,daftarakun,5,0)) -> 0 | H8: =IF(C8="","",VLOOKUP(C8,daftarakun,6,0)) -> 0 | I8: =SUMIF(KBNS,C8,JB) -> 0 | J8: =SUMIF(KBNS,C8,JK) -> 0 | K8: =IF(E8="Db",G8-H8+I8-J8,0) -> 0 | L8: =IF(E8="Kr",H8+J8-G8-I8,0) -> 0
B9: =IF(D9=0,0,1) -> 1 | C9: ='Formula (2)'!C8 -> 10001 | D9: =IF(C9="","",VLOOKUP(C9,daftarakun,2,0)) -> Kas | E9: =IF(C9="","",VLOOKUP(C9,daftarakun,4,0)) -> Db | F9: =IF(C9="","",VLOOKUP(C9,daftarakun,3,0)) -> Nrc | G9: =IF(C9="","",VLOOKUP(C9,daftarakun,5,0)) -> 100000 | H9: =IF(C9="","",VLOOKUP(C9,daftarakun,6,0)) -> 0 | I9: =SUMIF(KBNS,C9,JB) -> 0 | J9: =SUMIF(KBNS,C9,JK) -> 20000 | K9: =IF(E9="Db",G9-H9+I9-J9,0) -> 80000 | L9: =IF(E9="Kr",H9+J9-G9-I9,0) -> 0
B10: =IF(D10=0,0,1) -> 1 | C10: ='Formula (2)'!C9 -> 10002 | D10: =IF(C10="","",VLOOKUP(C10,daftarakun,2,0)) -> Persediaan Barang Dagang | E10: =IF(C10="","",VLOOKUP(C10,daftarakun,4,0)) -> Db | F10: =IF(C10="","",VLOOKUP(C10,daftarakun,3,0)) -> Nrc | G10: =IF(C10="","",VLOOKUP(C10,daftarakun,5,0)) -> 0 | H10: =IF(C10="","",VLOOKUP(C10,daftarakun,6,0)) -> 0 | I10: =SUMIF(KBNS,C10,JB) -> 0 | J10: =SUMIF(KBNS,C10,JK) -> 0 | K10: =IF(E10="Db",G10-H10+I10-J10,0) -> 0 | L10: =IF(E10="Kr",H10+J10-G10-I10,0) -> 0
B11: =IF(D11=0,0,1) -> 1 | C11: ='Formula (2)'!C10 -> 10003 | D11: =IF(C11="","",VLOOKUP(C11,daftarakun,2,0)) -> Piutang Usaha | E11: =IF(C11="","",VLOOKUP(C11,daftarakun,4,0)) -> Db | F11: =IF(C11="","",VLOOKUP(C11,daftarakun,3,0)) -> Nrc | G11: =IF(C11="","",VLOOKUP(C11,daftarakun,5,0)) -> 500000 | H11: =IF(C11="","",VLOOKUP(C11,daftarakun,6,0)) -> 0 | I11: =SUMIF(KBNS,C11,JB) -> 0 | J11: =SUMIF(KBNS,C11,JK) -> 0 | K11: =IF(E11="Db",G11-H11+I11-J11,0) -> 500000 | L11: =IF(E11="Kr",H11+J11-G11-I11,0) -> 0
B12: =IF(D12=0,0,1) -> 1 | C12: ='Formula (2)'!C11 -> 10004 | D12: =IF(C12="","",VLOOKUP(C12,daftarakun,2,0)) -> Piutang Pendapatan | E12: =IF(C12="","",VLOOKUP(C12,daftarakun,4,0)) -> Db | F12: =IF(C12="","",VLOOKUP(C12,daftarakun,3,0)) -> Nrc | G12: =IF(C12="","",VLOOKUP(C12,daftarakun,5,0)) -> 0 | H12: =IF(C12="","",VLOOKUP(C12,daftarakun,6,0)) -> 0 | I12: =SUMIF(KBNS,C12,JB) -> 0 | J12: =SUMIF(KBNS,C12,JK) -> 0 | K12: =IF(E12="Db",G12-H12+I12-J12,0) -> 0 | L12: =IF(E12="Kr",H12+J12-G12-I12,0) -> 0
B13: =IF(D13=0,0,1) -> 1 | C13: ='Formula (2)'!C12 -> 10005 | D13: =IF(C13="","",VLOOKUP(C13,daftarakun,2,0)) -> Wesel Tagih | E13: =IF(C13="","",VLOOKUP(C13,daftarakun,4,0)) -> Db | F13: =IF(C13="","",VLOOKUP(C13,daftarakun,3,0)) -> Nrc | G13: =IF(C13="","",VLOOKUP(C13,daftarakun,5,0)) -> 0 | H13: =IF(C13="","",VLOOKUP(C13,daftarakun,6,0)) -> 0 | I13: =SUMIF(KBNS,C13,JB) -> 0 | J13: =SUMIF(KBNS,C13,JK) -> 0 | K13: =IF(E13="Db",G13-H13+I13-J13,0) -> 0 | L13: =IF(E13="Kr",H13+J13-G13-I13,0) -> 0
B14: =IF(D14=0,0,1) -> 1 | C14: ='Formula (2)'!C13 -> 10006 | D14: =IF(C14="","",VLOOKUP(C14,daftarakun,2,0)) -> Perlengkapan Kantor | E14: =IF(C14="","",VLOOKUP(C14,daftarakun,4,0)) -> Db | F14: =IF(C14="","",VLOOKUP(C14,daftarakun,3,0)) -> Nrc | G14: =IF(C14="","",VLOOKUP(C14,daftarakun,5,0)) -> 0 | H14: =IF(C14="","",VLOOKUP(C14,daftarakun,6,0)) -> 0 | I14: =SUMIF(KBNS,C14,JB) -> 20000 | J14: =SUMIF(KBNS,C14,JK) -> 0 | K14: =IF(E14="Db",G14-H14+I14-J14,0) -> 20000 | L14: =IF(E14="Kr",H14+J14-G14-I14,0) -> 0
B15: =IF(D15=0,0,1) -> 1 | C15: ='Formula (2)'!C14 -> 10007 | D15: =IF(C15="","",VLOOKUP(C15,daftarakun,2,0)) -> Perlengkapan Toko | E15: =IF(C15="","",VLOOKUP(C15,daftarakun,4,0)) -> Db | F15: =IF(C15="","",VLOOKUP(C15,daftarakun,3,0)) -> Nrc | G15: =IF(C15="","",VLOOKUP(C15,daftarakun,5,0)) -> 0 | H15: =IF(C15="","",VLOOKUP(C15,daftarakun,6,0)) -> 0 | I15: =SUMIF(KBNS,C15,JB) -> 0 | J15: =SUMIF(KBNS,C15,JK) -> 0 | K15: =IF(E15="Db",G15-H15+I15-J15,0) -> 0 | L15: =IF(E15="Kr",H15+J15-G15-I15,0) -> 0
B16: =IF(D16=0,0,1) -> 1 | C16: ='Formula (2)'!C15 -> 10008 | D16: =IF(C16="","",VLOOKUP(C16,daftarakun,2,0)) -> Iklan Dibayar Dimuka | E16: =IF(C16="","",VLOOKUP(C16,daftarakun,4,0)) -> Db | F16: =IF(C16="","",VLOOKUP(C16,daftarakun,3,0)) -> Nrc | G16: =IF(C16="","",VLOOKUP(C16,daftarakun,5,0)) -> 0 | H16: =IF(C16="","",VLOOKUP(C16,daftarakun,6,0)) -> 0 | I16: =SUMIF(KBNS,C16,JB) -> 0 | J16: =SUMIF(KBNS,C16,JK) -> 0 | K16: =IF(E16="Db",G16-H16+I16-J16,0) -> 0 | L16: =IF(E16="Kr",H16+J16-G16-I16,0) -> 0
B17: =IF(D17=0,0,1) -> 1 | C17: ='Formula (2)'!C16 -> 10009 | D17: =IF(C17="","",VLOOKUP(C17,daftarakun,2,0)) -> Sewa Dibayar Dimuka | E17: =IF(C17="","",VLOOKUP(C17,daftarakun,4,0)) -> Db | F17: =IF(C17="","",VLOOKUP(C17,daftarakun,3,0)) -> Nrc | G17: =IF(C17="","",VLOOKUP(C17,daftarakun,5,0)) -> 0 | H17: =IF(C17="","",VLOOKUP(C17,daftarakun,6,0)) -> 0 | I17: =SUMIF(KBNS,C17,JB) -> 0 | J17: =SUMIF(KBNS,C17,JK) -> 0 | K17: =IF(E17="Db",G17-H17+I17-J17,0) -> 0 | L17: =IF(E17="Kr",H17+J17-G17-I17,0) -> 0
B18: =IF(D18=0,0,1) -> 1 | C18: ='Formula (2)'!C17 -> 10010 | D18: =IF(C18="","",VLOOKUP(C18,daftarakun,2,0)) -> Asuransi Dibayar Dimuka | E18: =IF(C18="","",VLOOKUP(C18,daftarakun,4,0)) -> Db | F18: =IF(C18="","",VLOOKUP(C18,daftarakun,3,0)) -> Nrc | G18: =IF(C18="","",VLOOKUP(C18,daftarakun,5,0)) -> 0 | H18: =IF(C18="","",VLOOKUP(C18,daftarakun,6,0)) -> 0 | I18: =SUMIF(KBNS,C18,JB) -> 0 | J18: =SUMIF(KBNS,C18,JK) -> 0 | K18: =IF(E18="Db",G18-H18+I18-J18,0) -> 0 | L18: =IF(E18="Kr",H18+J18-G18-I18,0) -> 0
B19: =IF(D19=0,0,1) -> 0 | C19: ='Formula (2)'!C18 -> 10011 | D19: =IF(C19="","",VLOOKUP(C19,daftarakun,2,0)) -> 0 | E19: =IF(C19="","",VLOOKUP(C19,daftarakun,4,0)) -> Db | F19: =IF(C19="","",VLOOKUP(C19,daftarakun,3,0)) -> Nrc | G19: =IF(C19="","",VLOOKUP(C19,daftarakun,5,0)) -> 0 | H19: =IF(C19="","",VLOOKUP(C19,daftarakun,6,0)) -> 0 | I19: =SUMIF(KBNS,C19,JB) -> 0 | J19: =SUMIF(KBNS,C19,JK) -> 0 | K19: =IF(E19="Db",G19-H19+I19-J19,0) -> 0 | L19: =IF(E19="Kr",H19+J19-G19-I19,0) -> 0
... B146: =IF(D146=0,0,1) -> 0 | C146: ='Formula (2)'!C145 -> 50030 | D146: =IF(C146="","",VLOOKUP(C146,daftarakun,2,0)) -> 0 | E146: =IF(C146="","",VLOOKUP(C146,daftarakun,4,0)) -> Db | F146: =IF(C146="","",VLOOKUP(C146,daftarakun,3,0)) -> Nrc | G146: =IF(C146="","",VLOOKUP(C146,daftarakun,5,0)) -> 0 | H146: =IF(C146="","",VLOOKUP(C146,daftarakun,6,0)) -> 0 | I146: =SUMIF(KBNS,C146,JB) -> 0 | J146: =SUMIF(KBNS,C146,JK) -> 0 | K146: =IF(E146="Db",G146-H146+I146-J146,0) -> 0 | L146: =IF(E146="Kr",H146+J146-G146-I146,0) -> 0
C147: Balancing statement | E147: Ʃ | G147: =SUM(G9:G75) -> 600000 | H147: =SUM(H9:H75) -> 0 | I147: =SUM(I9:I77) -> 20000 | J147: =SUM(J9:J77) -> 20000 | K147: =SUM(K9:K78) -> 600000 | L147: =SUM(L9:L77) -> 0

Sheet Worksheet (6)
B2: ='Ledger (4)'!D2 -> CV Max Picture
B3: Neraca Lajur
B4: ='Ledger (4)'!D5 -> Periode Desember 2021
B5: ='Jurnal Umum (3)'!G5 -> ~ Dilarang keras merubah (Apapun) yang bukan menjadi kepentingan Anda ! ~
B6: Kode | C6: Nama Akun | D6: SN | E6: Pos | F6: Saldo awal | J6: Neraca saldo | L6: Penyesuaian | N6: NSD | P6: Laba/Rugi | R6: Neraca
F7: Debit | G7: Kredit | H7: Debit | I7: Kredit | J7: Debit | K7: Kredit | L7: Debit | M7: Kredit | N7: Debit | O7: Kredit | P7: Debit | Q7: Kredit | R7: Debit | S7: Kredit
A8: =IF(C8=0,0,1) -> 1 | B8: ='Formula (2)'!C7 -> 10000 | C8: =IF(B8="","",VLOOKUP(B8,daftarakun,2,0)) -> Harta Lancar | D8: =IF(B8="","",VLOOKUP(B8,daftarakun,4,0)) -> Db | E8: =IF(B8="","",VLOOKUP(B8,daftarakun,3,0)) -> Nrc | F8: =IF(B8="","",VLOOKUP(B8,daftarakun,5,0)) -> 0 | G8: =IF(B8="","",VLOOKUP(B8,daftarakun,6,0)) -> 0 | H8: =SUMIF(KBNS,B8,JB) -> 0 | I8: =SUMIF(KBNS,B8,JK) -> 0 | J8: =IF(D8="Db",F8+H8-G8-I8,0) -> 0 | K8: =IF(D8="Kr",G8+I8-F8-H8,0) -> 0 | L8: =SUMIF(KBPNY,B8,JB) -> 0 | M8: =SUMIF(KBPNY,B8,JK) -> 0 | N8: =IF(D8="Db",J8+L8-K8-M8,0) -> 0 | O8: =IF(D8="Kr",K8+M8-J8-L8,0) -> 0 | P8: =IF(E8="Lr",N8,0) -> 0 | Q8: =IF(E8="Lr",O8,0) -> 0 | R8: =IF(E8="Nrc",N8,0) -> 0 | S8: =IF(E8="Nrc",O8,0) -> 0
A9: =IF(C9=0,0,1) -> 1 | B9: ='Formula (2)'!C8 -> 10001 | C9: =IF(B9="","",VLOOKUP(B9,daftarakun,2,0)) -> Kas | D9: =IF(B9="","",VLOOKUP(B9,daftarakun,4,0)) -> Db | E9: =IF(B9="","",VLOOKUP(B9,daftarakun,3,0)) -> Nrc | F9: =IF(B9="","",VLOOKUP(B9,daftarakun,5,0)) -> 100000 | G9: =IF(B9="","",VLOOKUP(B9,daftarakun,6,0)) -> 0 | H9: =SUMIF(KBNS,B9,JB) -> 0 | I9: =SUMIF(KBNS,B9,JK) -> 20000 | J9: =IF(D9="Db",F9+H9-G9-I9,0) -> 80000 | K9: =IF(D9="Kr",G9+I9-F9-H9,0) -> 0 | L9: =SUMIF(KBPNY,B9,JB) -> 0 | M9: =SUMIF(KBPNY,B9,JK) -> 0 | N9: =IF(D9="Db",J9+L9-K9-M9,0) -> 80000 | O9: =IF(D9="Kr",K9+M9-J9-L9,0) -> 0 | P9: =IF(E9="Lr",N9,0) -> 0 | Q9: =IF(E9="Lr",O9,0) -> 0 | R9: =IF(E9="Nrc",N9,0) -> 80000 | S9: =IF(E9="Nrc",O9,0) -> 0
A10: =IF(C10=0,0,1) -> 1 | B10: ='Formula (2)'!C9 -> 10002 | C10: =IF(B10="","",VLOOKUP(B10,daftarakun,2,0)) -> Persediaan Barang Dagang | D10: =IF(B10="","",VLOOKUP(B10,daftarakun,4,0)) -> Db | E10: =IF(B10="","",VLOOKUP(B10,daftarakun,3,0)) -> Nrc | F10: =IF(B10="","",VLOOKUP(B10,daftarakun,5,0)) -> 0 | G10: =IF(B10="","",VLOOKUP(B10,daftarakun,6,0)) -> 0 | H10: =SUMIF(KBNS,B10,JB) -> 0 | I10: =SUMIF(KBNS,B10,JK) -> 0 | J10: =IF(D10="Db",F10+H10-G10-I10,0) -> 0 | K10: =IF(D10="Kr",G10+I10-F10-H10,0) -> 0 | L10: =SUMIF(KBPNY,B10,JB) -> 0 | M10: =SUMIF(KBPNY,B10,JK) -> 0 | N10: =IF(D10="Db",J10+L10-K10-M10,0) -> 0 | O10: =IF(D10="Kr",K10+M10-J10-L10,0) -> 0 | P10: =IF(E10="Lr",N10,0) -> 0 | Q10: =IF(E10="Lr",O10,0) -> 0 | R10: =IF(E10="Nrc",N10,0) -> 0 | S10: =IF(E10="Nrc",O10,0) -> 0
A11: =IF(C11=0,0,1) -> 1 | B11: ='Formula (2)'!C10 -> 10003 | C11: =IF(B11="","",VLOOKUP(B11,daftarakun,2,0)) -> Piutang Usaha | D11: =IF(B11="","",VLOOKUP(B11,daftarakun,4,0)) -> Db | E11: =IF(B11="","",VLOOKUP(B11,daftarakun,3,0)) -> Nrc | F11: =IF(B11="","",VLOOKUP(B11,daftarakun,5,0)) -> 500000 | G11: =IF(B11="","",VLOOKUP(B11,daftarakun,6,0)) -> 0 | H11: =SUMIF(KBNS,B11,JB) -> 0 | I11: =SUMIF(KBNS,B11,JK) -> 0 | J11: =IF(D11="Db",F11+H11-G11-I11,0) -> 500000 | K11: =IF(D11="Kr",G11+I11-F11-H11,0) -> 0 | L11: =SUMIF(KBPNY,B11,JB) -> 0 | M11: =SUMIF(KBPNY,B11,JK) -> 0 | N11: =IF(D11="Db",J11+L11-K11-M11,0) -> 500000 | O11: =IF(D11="Kr",K11+M11-J11-L11,0) -> 0 | P11: =IF(E11="Lr",N11,0) -> 0 | Q11: =IF(E11="Lr",O11,0) -> 0 | R11: =IF(E11="Nrc",N11,0) -> 500000 | S11: =IF(E11="Nrc",O11,0) -> 0
A12: =IF(C12=0,0,1) -> 1 | B12: ='Formula (2)'!C11 -> 10004 | C12: =IF(B12="","",VLOOKUP(B12,daftarakun,2,0)) -> Piutang Pendapatan | D12: =IF(B12="","",VLOOKUP(B12,daftarakun,4,0)) -> Db | E12: =IF(B12="","",VLOOKUP(B12,daftarakun,3,0)) -> Nrc | F12: =IF(B12="","",VLOOKUP(B12,daftarakun,5,0)) -> 0 | G12: =IF(B12="","",VLOOKUP(B12,daftarakun,6,0)) -> 0 | H12: =SUMIF(KBNS,B12,JB) -> 0 | I12: =SUMIF(KBNS,B12,JK) -> 0 | J12: =IF(D12="Db",F12+H12-G12-I12,0) -> 0 | K12: =IF(D12="Kr",G12+I12-F12-H12,0) -> 0 | L12: =SUMIF(KBPNY,B12,JB) -> 0 | M12: =SUMIF(KBPNY,B12,JK) -> 0 | N12: =IF(D12="Db",J12+L12-K12-M12,0) -> 0 | O12: =IF(D12="Kr",K12+M12-J12-L12,0) -> 0 | P12: =IF(E12="Lr",N12,0) -> 0 | Q12: =IF(E12="Lr",O12,0) -> 0 | R12: =IF(E12="Nrc",N12,0) -> 0 | S12: =IF(E12="Nrc",O12,0) -> 0
A13: =IF(C13=0,0,1) -> 1 | B13: ='Formula (2)'!C12 -> 10005 | C13: =IF(B13="","",VLOOKUP(B13,daftarakun,2,0)) -> Wesel Tagih | D13: =IF(B13="","",VLOOKUP(B13,daftarakun,4,0)) -> Db | E13: =IF(B13="","",VLOOKUP(B13,daftarakun,3,0)) -> Nrc | F13: =IF(B13="","",VLOOKUP(B13,daftarakun,5,0)) -> 0 | G13: =IF(B13="","",VLOOKUP(B13,daftarakun,6,0)) -> 0 | H13: =SUMIF(KBNS,B13,JB) -> 0 | I13: =SUMIF(KBNS,B13,JK) -> 0 | J13: =IF(D13="Db",F13+H13-G13-I13,0) -> 0 | K13: =IF(D13="Kr",G13+I13-F13-H13,0) -> 0 | L13: =SUMIF(KBPNY,B13,JB) -> 0 | M13: =SUMIF(KBPNY,B13,JK) -> 0 | N13: =IF(D13="Db",J13+L13-K13-M13,0) -> 0 | O13: =IF(D13="Kr",K13+M13-J13-L13,0) -> 0 | P13: =IF(E13="Lr",N13,0) -> 0 | Q13: =IF(E13="Lr",O13,0) -> 0 | R13: =IF(E13="Nrc",N13,0) -> 0 | S13: =IF(E13="Nrc",O13,0) -> 0
A14: =IF(C14=0,0,1) -> 1 | B14: ='Formula (2)'!C13 -> 10006 | C14: =IF(B14="","",VLOOKUP(B14,daftarakun,2,0)) -> Perlengkapan Kantor | D14: =IF(B14="","",VLOOKUP(B14,daftarakun,4,0)) -> Db | E14: =IF(B14="","",VLOOKUP(B14,daftarakun,3,0)) -> Nrc | F14: =IF(B14="","",VLOOKUP(B14,daftarakun,5,0)) -> 0 | G14: =IF(B14="","",VLOOKUP(B14,daftarakun,6,0)) -> 0 | H14: =SUMIF(KBNS,B14,JB) -> 20000 | I14: =SUMIF(KBNS,B14,JK) -> 0 | J14: =IF(D14="Db",F14+H14-G14-I14,0) -> 20000 | K14: =IF(D14="Kr",G14+I14-F14-H14,0) -> 0 | L14: =SUMIF(KBPNY,B14,JB) -> 0 | M14: =SUMIF(KBPNY,B14,JK) -> 10000 | N14: =IF(D14="Db",J14+L14-K14-M14,0) -> 10000 | O14: =IF(D14="Kr",K14+M14-J14-L14,0) -> 0 | P14: =IF(E14="Lr",N14,0) -> 0 | Q14: =IF(E14="Lr",O14,0) -> 0 | R14: =IF(E14="Nrc",N14,0) -> 10000 | S14: =IF(E14="Nrc",O14,0) -> 0
A15: =IF(C15=0,0,1) -> 1 | B15: ='Formula (2)'!C14 -> 10007 | C15: =IF(B15="","",VLOOKUP(B15,daftarakun,2,0)) -> Perlengkapan Toko | D15: =IF(B15="","",VLOOKUP(B15,daftarakun,4,0)) -> Db | E15: =IF(B15="","",VLOOKUP(B15,daftarakun,3,0)) -> Nrc | F15: =IF(B15="","",VLOOKUP(B15,daftarakun,5,0)) -> 0 | G15: =IF(B15="","",VLOOKUP(B15,daftarakun,6,0)) -> 0 | H15: =SUMIF(KBNS,B15,JB) -> 0 | I15: =SUMIF(KBNS,B15,JK) -> 0 | J15: =IF(D15="Db",F15+H15-G15-I15,0) -> 0 | K15: =IF(D15="Kr",G15+I15-F15-H15,0) -> 0 | L15: =SUMIF(KBPNY,B15,JB) -> 0 | M15: =SUMIF(KBPNY,B15,JK) -> 0 | N15: =IF(D15="Db",J15+L15-K15-M15,0) -> 0 | O15: =IF(D15="Kr",K15+M15-J15-L15,0) -> 0 | P15: =IF(E15="Lr",N15,0) -> 0 | Q15: =IF(E15="Lr",O15,0) -> 0 | R15: =IF(E15="Nrc",N15,0) -> 0 | S15: =IF(E15="Nrc",O15,0) -> 0
A16: =IF(C16=0,0,1) -> 1 | B16: ='Formula (2)'!C15 -> 10008 | C16: =IF(B16="","",VLOOKUP(B16,daftarakun,2,0)) -> Iklan Dibayar Dimuka | D16: =IF(B16="","",VLOOKUP(B16,daftarakun,4,0)) -> Db | E16: =IF(B16="","",VLOOKUP(B16,daftarakun,3,0)) -> Nrc | F16: =IF(B16="","",VLOOKUP(B16,daftarakun,5,0)) -> 0 | G16: =IF(B16="","",VLOOKUP(B16,daftarakun,6,0)) -> 0 | H16: =SUMIF(KBNS,B16,JB) -> 0 | I16: =SUMIF(KBNS,B16,JK) -> 0 | J16: =IF(D16="Db",F16+H16-G16-I16,0) -> 0 | K16: =IF(D16="Kr",G16+I16-F16-H16,0) -> 0 | L16: =SUMIF(KBPNY,B16,JB) -> 0 | M16: =SUMIF(KBPNY,B16,JK) -> 0 | N16: =IF(D16="Db",J16+L16-K16-M16,0) -> 0 | O16: =IF(D16="Kr",K16+M16-J16-L16,0) -> 0 | P16: =IF(E16="Lr",N16,0) -> 0 | Q16: =IF(E16="Lr",O16,0) -> 0 | R16: =IF(E16="Nrc",N16,0) -> 0 | S16: =IF(E16="Nrc",O16,0) -> 0
A17: =IF(C17=0,0,1) -> 1 | B17: ='Formula (2)'!C16 -> 10009 | C17: =IF(B17="","",VLOOKUP(B17,daftarakun,2,0)) -> Sewa Dibayar Dimuka | D17: =IF(B17="","",VLOOKUP(B17,daftarakun,4,0)) -> Db | E17: =IF(B17="","",VLOOKUP(B17,daftarakun,3,0)) -> Nrc | F17: =IF(B17="","",VLOOKUP(B17,daftarakun,5,0)) -> 0 | G17: =IF(B17="","",VLOOKUP(B17,daftarakun,6,0)) -> 0 | H17: =SUMIF(KBNS,B17,JB) -> 0 | I17: =SUMIF(KBNS,B17,JK) -> 0 | J17: =IF(D17="Db",F17+H17-G17-I17,0) -> 0 | K17: =IF(D17="Kr",G17+I17-F17-H17,0) -> 0 | L17: =SUMIF(KBPNY,B17,JB) -> 0 | M17: =SUMIF(KBPNY,B17,JK) -> 0 | N17: =IF(D17="Db",J17+L17-K17-M17,0) -> 0 | O17: =IF(D17="Kr",K17+M17-J17-L17,0) -> 0 | P17: =IF(E17="Lr",N17,0) -> 0 | Q17: =IF(E17="Lr",O17,0) -> 0 | R17: =IF(E17="Nrc",N17,0) -> 0 | S17: =IF(E17="Nrc",O17,0) -> 0
A18: =IF(C18=0,0,1) -> 1 | B18: ='Formula (2)'!C17 -> 10010 | C18: =IF(B18="","",VLOOKUP(B18,daftarakun,2,0)) -> Asuransi Dibayar Dimuka | D18: =IF(B18="","",VLOOKUP(B18,daftarakun,4,0)) -> Db | E18: =IF(B18="","",VLOOKUP(B18,daftarakun,3,0)) -> Nrc | F18: =IF(B18="","",VLOOKUP(B18,daftarakun,5,0)) -> 0 | G18: =IF(B18="","",VLOOKUP(B18,daftarakun,6,0)) -> 0 | H18: =SUMIF(KBNS,B18,JB) -> 0 | I18: =SUMIF(KBNS,B18,JK) -> 0 | J18: =IF(D18="Db",F18+H18-G18-I18,0) -> 0 | K18: =IF(D18="Kr",G18+I18-F18-H18,0) -> 0 | L18: =SUMIF(KBPNY,B18,JB) -> 0 | M18: =SUMIF(KBPNY,B18,JK) -> 0 | N18: =IF(D18="Db",J18+L18-K18-M18,0) -> 0 | O18: =IF(D18="Kr",K18+M18-J18-L18,0) -> 0 | P18: =IF(E18="Lr",N18,0) -> 0 | Q18: =IF(E18="Lr",O18,0) -> 0 | R18: =IF(E18="Nrc",N18,0) -> 0 | S18: =IF(E18="Nrc",O18,0) -> 0
A19: =IF(C19=0,0,1) -> 0 | B19: ='Formula (2)'!C18 -> 10011 | C19: =IF(B19="","",VLOOKUP(B19,daftarakun,2,0)) -> 0 | D19: =IF(B19="","",VLOOKUP(B19,daftarakun,4,0)) -> Db | E19: =IF(B19="","",VLOOKUP(B19,daftarakun,3,0)) -> Nrc | F19: =IF(B19="","",VLOOKUP(B19,daftarakun,5,0)) -> 0 | G19: =IF(B19="","",VLOOKUP(B19,daftarakun,6,0)) -> 0 | H19: =SUMIF(KBNS,B19,JB) -> 0 | I19: =SUMIF(KBNS,B19,JK) -> 0 | J19: =IF(D19="Db",F19+H19-G19-I19,0) -> 0 | K19: =IF(D19="Kr",G19+I19-F19-H19,0) -> 0 | L19: =SUMIF(KBPNY,B19,JB) -> 0 | M19: =SUMIF(KBPNY,B19,JK) -> 0 | N19: =IF(D19="Db",J19+L19-K19-M19,0) -> 0 | O19: =IF(D19="Kr",K19+M19-J19-L19,0) -> 0 | P19: =IF(E19="Lr",N19,0) -> 0 | Q19: =IF(E19="Lr",O19,0) -> 0 | R19: =IF(E19="Nrc",N19,0) -> 0 | S19: =IF(E19="Nrc",O19,0) -> 0
... A146: =IF(C146=0,0,1) -> 0 | B146: ='Formula (2)'!C145 -> 50030 | C146: =IF(B146="","",VLOOKUP(B146,daftarakun,2,0)) -> 0 | D146: =IF(B146="","",VLOOKUP(B146,daftarakun,4,0)) -> Db | E146: =IF(B146="","",VLOOKUP(B146,daftarakun,3,0)) -> Nrc | F146: =IF(B146="","",VLOOKUP(B146,daftarakun,5,0)) -> 0 | G146: =IF(B146="","",VLOOKUP(B146,daftarakun,6,0)) -> 0 | H146: =SUMIF(KBNS,B146,JB) -> 0 | I146: =SUMIF(KBNS,B146,JK) -> 0 | J146: =IF(D146="Db",F146+H146-G146-I146,0) -> 0 | K146: =IF(D146="Kr",G146+I146-F146-H146,0) -> 0 | L146: =SUMIF(KBPNY,B146,JB) -> 0 | M146: =SUMIF(KBPNY,B146,JK) -> 0 | N146: =IF(D146="Db",J146+L146-K146-M146,0) -> 0 | O146: =IF(D146="Kr",K146+M146-J146-L146,0) -> 0 | P146: =IF(E146="Lr",N146,0) -> 0 | Q146: =IF(E146="Lr",O146,0) -> 0 | R146: =IF(E146="Nrc",N146,0) -> 0 | S146: =IF(E146="Nrc",O146,0) -> 0
B147: Balancing statement | D147: Ʃ | F147: =SUM(F9:F146) -> 1100000 | G147: =SUM(G9:G146) -> 1100000 | H147: =SUM(H9:H146) -> 20000 | I147: =SUM(I9:I146) -> 20000 | J147: =SUM(J9:J146) -> 1100000 | K147: =SUM(K9:K146) -> 1100000 | L147: =SUM(L9:L146) -> 10000 | M147: =SUM(M9:M146) -> 10000 | ... S147: =SUM(S9:S146) -> 100000
P148: =IF(Q147>P147,"Laba","Rugi") -> Laba | Q148: =IF(P147>Q147,P147-Q147,Q147-P147) -> 490000 | R148: CEK | S148: =IF(R147>S147,R147-S147,S147-R147) -> 490000

Sheet Profit And Loss (7)
B2: ='Worksheet (6)'!B2:S2 -> CV Max Picture
B3: Laba rugi (Singel Step)
B4: ='Worksheet (6)'!B4:S4 -> Periode Desember 2021
B5: ='Worksheet (6)'!B5:S5 -> ~ Dilarang keras merubah (Apapun) yang bukan menjadi kepentingan Anda ! ~
B6: Kode | C6: Keterangan | D6: SN | E6: Debet | F6: Kredit | G6: Saldo
A7: =IF(C7=0,0,1) -> 1 | B7: ='Worksheet (6)'!B94 -> 40000 | C7: =VLOOKUP(B7,neracalajur,2,0) -> Pendapatan oprasional | D7: =VLOOKUP(B7,neracalajur,3,0) -> Kr | E7: =VLOOKUP(B7,neracalajur,15,0) -> 0 | F7: =VLOOKUP(B7,neracalajur,16,0) -> 0 | G7: =IF(D7="Kr",F7-E7,E7-F7) -> 0
A8: =IF(C8=0,0,1) -> 1 | B8: ='Worksheet (6)'!B95 -> 40001 | C8: =VLOOKUP(B8,neracalajur,2,0) -> Pendapatan Bunga | D8: =VLOOKUP(B8,neracalajur,3,0) -> Kr | E8: =VLOOKUP(B8,neracalajur,15,0) -> 0 | F8: =VLOOKUP(B8,neracalajur,16,0) -> 0 | G8: =IF(D8="Kr",F8-E8,E8-F8) -> 0
A9: =IF(C9=0,0,1) -> 1 | B9: ='Worksheet (6)'!B96 -> 40002 | C9: =VLOOKUP(B9,neracalajur,2,0) -> Retur Penjualan | D9: =VLOOKUP(B9,neracalajur,3,0) -> Kr | E9: =VLOOKUP(B9,neracalajur,15,0) -> 0 | F9: =VLOOKUP(B9,neracalajur,16,0) -> 0 | G9: =IF(D9="Kr",F9-E9,E9-F9) -> 0
A10: =IF(C10=0,0,1) -> 1 | B10: ='Worksheet (6)'!B97 -> 40003 | C10: =VLOOKUP(B10,neracalajur,2,0) -> Potongan Penjualan | D10: =VLOOKUP(B10,neracalajur,3,0) -> Kr | E10: =VLOOKUP(B10,neracalajur,15,0) -> 0 | F10: =VLOOKUP(B10,neracalajur,16,0) -> 0 | G10: =IF(D10="Kr",F10-E10,E10-F10) -> 0
A11: =IF(C11=0,0,1) -> 1 | B11: ='Worksheet (6)'!B98 -> 40004 | C11: =VLOOKUP(B11,neracalajur,2,0) -> Pembelian | D11: =VLOOKUP(B11,neracalajur,3,0) -> Kr | E11: =VLOOKUP(B11,neracalajur,15,0) -> 0 | F11: =VLOOKUP(B11,neracalajur,16,0) -> 0 | G11: =IF(D11="Kr",F11-E11,E11-F11) -> 0
A12: =IF(C12=0,0,1) -> 1 | B12: ='Worksheet (6)'!B99 -> 40005 | C12: =VLOOKUP(B12,neracalajur,2,0) -> Retur Pembelian | D12: =VLOOKUP(B12,neracalajur,3,0) -> Kr | E12: =VLOOKUP(B12,neracalajur,15,0) -> 0 | F12: =VLOOKUP(B12,neracalajur,16,0) -> 1000000 | G12: =IF(D12="Kr",F12-E12,E12-F12) -> 1000000
A13: =IF(C13=0,0,1) -> 1 | B13: ='Worksheet (6)'!B100 -> 40006 | C13: =VLOOKUP(B13,neracalajur,2,0) -> Beban Angkut Pembelian | D13: =VLOOKUP(B13,neracalajur,3,0) -> Kr | E13: =VLOOKUP(B13,neracalajur,15,0) -> 0 | F13: =VLOOKUP(B13,neracalajur,16,0) -> 0 | G13: =IF(D13="Kr",F13-E13,E13-F13) -> 0
A14: =IF(C14=0,0,1) -> 1 | B14: ='Worksheet (6)'!B101 -> 40007 | C14: =VLOOKUP(B14,neracalajur,2,0) -> IRL | D14: =VLOOKUP(B14,neracalajur,3,0) -> Kr | E14: =VLOOKUP(B14,neracalajur,15,0) -> 0 | F14: =VLOOKUP(B14,neracalajur,16,0) -> 0 | G14: =IF(D14="Kr",F14-E14,E14-F14) -> 0
A15: =IF(C15=0,0,1) -> 1 | B15: ='Worksheet (6)'!B102 -> 40008 | C15: =VLOOKUP(B15,neracalajur,2,0) -> Potongan Pembelian | D15: =VLOOKUP(B15,neracalajur,3,0) -> Kr | E15: =VLOOKUP(B15,neracalajur,15,0) -> 0 | F15: =VLOOKUP(B15,neracalajur,16,0) -> 0 | G15: =IF(D15="Kr",F15-E15,E15-F15) -> 0
A16: =IF(C16=0,0,1) -> 0 | B16: ='Worksheet (6)'!B103 -> 40009 | C16: =VLOOKUP(B16,neracalajur,2,0) -> 0 | D16: =VLOOKUP(B16,neracalajur,3,0) -> Db | E16: =VLOOKUP(B16,neracalajur,15,0) -> 0 | F16: =VLOOKUP(B16,neracalajur,16,0) -> 0 | G16: =IF(D16="Kr",F16-E16,E16-F16) -> 0
A17: =IF(C17=0,0,1) -> 0 | B17: ='Worksheet (6)'!B104 -> 40010 | C17: =VLOOKUP(B17,neracalajur,2,0) -> 0 | D17: =VLOOKUP(B17,neracalajur,3,0) -> Db | E17: =VLOOKUP(B17,neracalajur,15,0) -> 0 | F17: =VLOOKUP(B17,neracalajur,16,0) -> 0 | G17: =IF(D17="Kr",F17-E17,E17-F17) -> 0
A18: =IF(C18=0,0,1) -> 1 | B18: ='Worksheet (6)'!B105 -> 41000 | C18: =VLOOKUP(B18,neracalajur,2,0) -> Pendapatan Non Oprasional | D18: =VLOOKUP(B18,neracalajur,3,0) -> Kr | E18: =VLOOKUP(B18,neracalajur,15,0) -> 0 | F18: =VLOOKUP(B18,neracalajur,16,0) -> 0 | G18: =IF(D18="Kr",F18-E18,E18-F18) -> 0
... A28: =IF(C28=0,0,1) -> 0 | B28: ='Worksheet (6)'!B115 -> 41010 | C28: =VLOOKUP(B28,neracalajur,2,0) -> 0 | D28: =VLOOKUP(B28,neracalajur,3,0) -> Db | E28: =VLOOKUP(B28,neracalajur,15,0) -> 0 | F28: =VLOOKUP(B28,neracalajur,16,0) -> 0 | G28: =IF(D28="Kr",F28-E28,E28-F28) -> 0
A29: =IF(C29=0,0,1) -> 1 | C29: Total Pendapatan | D29: Ʃ | E29: =SUM(E7:E17) -> 0 | F29: =SUM(F7:F17) -> 1000000 | G29: =IF(E29>F29,E29-F29,F29-E29) -> 1000000
A30: =IF(C30=0,0,1) -> 0
A31: =IF(C31=0,0,1) -> 1 | B31: ='Worksheet (6)'!B116 -> 50000 | C31: =VLOOKUP(B31,neracalajur,2,0) -> Beban Oprasional | D31: =VLOOKUP(B31,neracalajur,3,0) -> Db | E31: =VLOOKUP(B31,neracalajur,15,0) -> 0 | F31: =VLOOKUP(B31,neracalajur,16,0) -> 0 | G31: =IF(D31="Kr",F31-E31,E31-F31) -> 0
A32: =IF(C32=0,0,1) -> 1 | B32: ='Worksheet (6)'!B117 -> 50001 | C32: =VLOOKUP(B32,neracalajur,2,0) -> Beban Gaji Toko | D32: =VLOOKUP(B32,neracalajur,3,0) -> Db | E32: =VLOOKUP(B32,neracalajur,15,0) -> 500000 | F32: =VLOOKUP(B32,neracalajur,16,0) -> 0 | G32: =IF(D32="Kr",F32-E32,E32-F32) -> 500000
A33: =IF(C33=0,0,1) -> 1 | B33: ='Worksheet (6)'!B118 -> 50002 | C33: =VLOOKUP(B33,neracalajur,2,0) -> Beban Gaji Kantor | D33: =VLOOKUP(B33,neracalajur,3,0) -> Db | E33: =VLOOKUP(B33,neracalajur,15,0) -> 0 | F33: =VLOOKUP(B33,neracalajur,16,0) -> 0 | G33: =IF(D33="Kr",F33-E33,E33-F33) -> 0
A34: =IF(C34=0,0,1) -> 1 | B34: ='Worksheet (6)'!B119 -> 50003 | C34: =VLOOKUP(B34,neracalajur,2,0) -> Beban Sewa Lahan | D34: =VLOOKUP(B34,neracalajur,3,0) -> Db | E34: =VLOOKUP(B34,neracalajur,15,0) -> 0 | F34: =VLOOKUP(B34,neracalajur,16,0) -> 0 | G34: =IF(D34="Kr",F34-E34,E34-F34) -> 0
A35: =IF(C35=0,0,1) -> 1 | B35: ='Worksheet (6)'!B120 -> 50004 | C35: =VLOOKUP(B35,neracalajur,2,0) -> Beban Asuransi | D35: =VLOOKUP(B35,neracalajur,3,0) -> Db | E35: =VLOOKUP(B35,neracalajur,15,0) -> 0 | F35: =VLOOKUP(B35,neracalajur,16,0) -> 0 | G35: =IF(D35="Kr",F35-E35,E35-F35) -> 0
A36: =IF(C36=0,0,1) -> 1 | B36: ='Worksheet (6)'!B121 -> 50005 | C36: =VLOOKUP(B36,neracalajur,2,0) -> Beban Penyesuaian Piutang | D36: =VLOOKUP(B36,neracalajur,3,0) -> Db | E36: =VLOOKUP(B36,neracalajur,15,0) -> 0 | F36: =VLOOKUP(B36,neracalajur,16,0) -> 0 | G36: =IF(D36="Kr",F36-E36,E36-F36) -> 0
A37: =IF(C37=0,0,1) -> 1 | B37: ='Worksheet (6)'!B122 -> 50006 | C37: =VLOOKUP(B37,neracalajur,2,0) -> Beban Perlengkapan Kantor | D37: =VLOOKUP(B37,neracalajur,3,0) -> Db | E37: =VLOOKUP(B37,neracalajur,15,0) -> 10000 | F37: =VLOOKUP(B37,neracalajur,16,0) -> 0 | G37: =IF(D37="Kr",F37-E37,E37-F37) -> 10000
A38: =IF(C38=0,0,1) -> 1 | B38: ='Worksheet (6)'!B123 -> 50007 | C38: =VLOOKUP(B38,neracalajur,2,0) -> Beban Perlengkapan Toko | D38: =VLOOKUP(B38,neracalajur,3,0) -> Db | E38: =VLOOKUP(B38,neracalajur,15,0) -> 0 | F38: =VLOOKUP(B38,neracalajur,16,0) -> 0 | G38: =IF(D38="Kr",F38-E38,E38-F38) -> 0
A39: =IF(C39=0,0,1) -> 1 | B39: ='Worksheet (6)'!B124 -> 50008 | C39: =VLOOKUP(B39,neracalajur,2,0) -> Beban Iklan | D39: =VLOOKUP(B39,neracalajur,3,0) -> Db | E39: =VLOOKUP(B39,neracalajur,15,0) -> 0 | F39: =VLOOKUP(B39,neracalajur,16,0) -> 0 | G39: =IF(D39="Kr",F39-E39,E39-F39) -> 0
A40: =IF(C40=0,0,1) -> 1 | B40: ='Worksheet (6)'!B125 -> 50009 | C40: =VLOOKUP(B40,neracalajur,2,0) -> Beban Penyusutan Peralatan kantor | D40: =VLOOKUP(B40,neracalajur,3,0) -> Db | E40: =VLOOKUP(B40,neracalajur,15,0) -> 0 | F40: =VLOOKUP(B40,neracalajur,16,0) -> 0 | G40: =IF(D40="Kr",F40-E40,E40-F40) -> 0
A41: =IF(C41=0,0,1) -> 1 | B41: ='Worksheet (6)'!B126 -> 50010 | C41: =VLOOKUP(B41,neracalajur,2,0) -> Beban Penyusutan Gedung | D41: =VLOOKUP(B41,neracalajur,3,0) -> Db | E41: =VLOOKUP(B41,neracalajur,15,0) -> 0 | F41: =VLOOKUP(B41,neracalajur,16,0) -> 0 | G41: =IF(D41="Kr",F41-E41,E41-F41) -> 0
A42: =IF(C42=0,0,1) -> 1 | B42: ='Worksheet (6)'!B127 -> 50011 | C42: =VLOOKUP(B42,neracalajur,2,0) -> Beban Bunga | D42: =VLOOKUP(B42,neracalajur,3,0) -> Db | E42: =VLOOKUP(B42,neracalajur,15,0) -> 0 | F42: =VLOOKUP(B42,neracalajur,16,0) -> 0 | G42: =IF(D42="Kr",F42-E42,E42-F42) -> 0
... A61: =IF(C61=0,0,1) -> 0 | B61: ='Worksheet (6)'!B146 -> 50030 | C61: =VLOOKUP(B61,neracalajur,2,0) -> 0 | D61: =VLOOKUP(B61,neracalajur,3,0) -> Db | E61: =VLOOKUP(B61,neracalajur,15,0) -> 0 | F61: =VLOOKUP(B61,neracalajur,16,0) -> 0 | G61: =IF(D61="Kr",F61-E61,E61-F61) -> 0
C62: Total Pendapatan | D62: Ʃ | E62: =SUM(E31:E52) -> 510000 | F62: =SUM(F31:F49) -> 0 | G62: =E62-F62 -> 510000
B63: =IF('Worksheet (6)'!$P$148="Rugi","Rugi Bersih Keseluruhan","Laba bersih Keseluruhan") -> Laba bersih Keseluruhan | E63: Ʃ | G63: =IF(G29>G62,G29-G62,G62-G29) -> 490000

Sheet Changes Capital Statement (9)
B2: ='Worksheet (6)'!B2:S2 -> CV Max Picture
B3: Laporan perubahan Modal
B4: ='Worksheet (6)'!B4:S4 -> Periode Desember 2021
B5: ='Worksheet (6)'!B5:S5 -> ~ Dilarang keras merubah (Apapun) yang bukan menjadi kepentingan Anda ! ~
B6: Kode | C6: Keterangan | D6: Saldo | F6: Posisi
F7: Menambah | G7: Mengurangi
B8: 30000 | C8: =VLOOKUP(B8,neracalajur,2,0) -> Modal/Ekuitas | D8: =VLOOKUP(B8,neracalajur,13,0) -> 0 | E8: =VLOOKUP(B8,neracalajur,14,0) -> 100000 | F8: =E8 -> 100000
B10: =IF(C10="Laba","(+)","(-)") -> (+) | C10: ='Worksheet (6)'!$P$148 -> Laba | D10: =IF($C$10="Rugi",'Worksheet (6)'!R148,"") | E10: =IF($C$10="Laba",'Worksheet (6)'!S148,"") -> 490000 | F10: =IF($C$10="Laba",E10,"") -> 490000 | G10: =IF($C$10="Rugi",D10,"")
B12: 30001 | C12: =VLOOKUP(B12,neracalajur,2,0) -> Prive | D12: =VLOOKUP(B12,neracalajur,13,0) -> 0 | E12: =VLOOKUP(B12,neracalajur,14,0) -> 0 | G12: =D12 -> 0
F13: =SUM(F8:F12) -> 590000 | G13: =SUM(G8:G12) -> 0
F14: =IF(G13>F13,G13-F13,0) -> 0 | G14: =IF(F13>G13,F13-G13,0) -> 590000
F15: =IF('Worksheet (6)'!$P$148="Laba","Surplus (+)","Devisit (-)") -> Surplus (+)

Sheet Analisis (10)
B2: ='Changes Capital Statement (9)'!B2 -> CV Max Picture
B3: Analisis Laporan
B4: ='Changes Capital Statement (9)'!B4 -> Periode Desember 2021
B5: ='Changes Capital Statement (9)'!B5 -> ~ Dilarang keras merubah (Apapun) yang bukan menjadi kepentingan Anda ! ~
B6: Kode | C6: Keterangan | D6: Posisi
D7: Menambah | E7: Mengurangi
B8: 30000 | C8: =VLOOKUP(B8,neracalajur,2,0) -> Modal/Ekuitas | D8: ='Changes Capital Statement (9)'!G14 -> 590000
B9: (-) | C9: Laba Bersih | D9: ='Changes Capital Statement (9)'!F10 -> 490000 | E9: ='Changes Capital Statement (9)'!G10
D10: =IF('Worksheet (6)'!$P$148="Laba","Surplus (+)","Devisit (-)") -> Surplus (+)

Sheet Laporan PK Pembantu (10.2)
B2: ='Worksheet (6)'!B8 -> 10000 | C2: =VLOOKUP(B2,neracalajur,2,0) -> Harta Lancar | D2: =VLOOKUP(B2,neracalajur,3,0) -> Db | E2: =VLOOKUP(B2,neracalajur,17,0) -> 0 | F2: =VLOOKUP(B2,neracalajur,18,0) -> 0
B3: ='Worksheet (6)'!B9 -> 10001 | C3: =VLOOKUP(B3,neracalajur,2,0) -> Kas | D3: =VLOOKUP(B3,neracalajur,3,0) -> Db | E3: =VLOOKUP(B3,neracalajur,17,0) -> 80000 | F3: =VLOOKUP(B3,neracalajur,18,0) -> 0
B4: ='Worksheet (6)'!B10 -> 10002 | C4: =VLOOKUP(B4,neracalajur,2,0) -> Persediaan Barang Dagang | D4: =VLOOKUP(B4,neracalajur,3,0) -> Db | E4: =VLOOKUP(B4,neracalajur,17,0) -> 0 | F4: =VLOOKUP(B4,neracalajur,18,0) -> 0
B5: ='Worksheet (6)'!B11 -> 10003 | C5: =VLOOKUP(B5,neracalajur,2,0) -> Piutang Usaha | D5: =VLOOKUP(B5,neracalajur,3,0) -> Db | E5: =VLOOKUP(B5,neracalajur,17,0) -> 500000 | F5: =VLOOKUP(B5,neracalajur,18,0) -> 0
B6: ='Worksheet (6)'!B12 -> 10004 | C6: =VLOOKUP(B6,neracalajur,2,0) -> Piutang Pendapatan | D6: =VLOOKUP(B6,neracalajur,3,0) -> Db | E6: =VLOOKUP(B6,neracalajur,17,0) -> 0 | F6: =VLOOKUP(B6,neracalajur,18,0) -> 0
B7: ='Worksheet (6)'!B13 -> 10005 | C7: =VLOOKUP(B7,neracalajur,2,0) -> Wesel Tagih | D7: =VLOOKUP(B7,neracalajur,3,0) -> Db | E7: =VLOOKUP(B7,neracalajur,17,0) -> 0 | F7: =VLOOKUP(B7,neracalajur,18,0) -> 0
B8: ='Worksheet (6)'!B14 -> 10006 | C8: =VLOOKUP(B8,neracalajur,2,0) -> Perlengkapan Kantor | D8: =VLOOKUP(B8,neracalajur,3,0) -> Db | E8: =VLOOKUP(B8,neracalajur,17,0) -> 10000 | F8: =VLOOKUP(B8,neracalajur,18,0) -> 0
B9: ='Worksheet (6)'!B15 -> 10007 | C9: =VLOOKUP(B9,neracalajur,2,0) -> Perlengkapan Toko | D9: =VLOOKUP(B9,neracalajur,3,0) -> Db | E9: =VLOOKUP(B9,neracalajur,17,0) -> 0 | F9: =VLOOKUP(B9,neracalajur,18,0) -> 0
B10: ='Worksheet (6)'!B16 -> 10008 | C10: =VLOOKUP(B10,neracalajur,2,0) -> Iklan Dibayar Dimuka | D10: =VLOOKUP(B10,neracalajur,3,0) -> Db | E10: =VLOOKUP(B10,neracalajur,17,0) -> 0 | F10: =VLOOKUP(B10,neracalajur,18,0) -> 0
B11: ='Worksheet (6)'!B17 -> 10009 | C11: =VLOOKUP(B11,neracalajur,2,0) -> Sewa Dibayar Dimuka | D11: =VLOOKUP(B11,neracalajur,3,0) -> Db | E11: =VLOOKUP(B11,neracalajur,17,0) -> 0 | F11: =VLOOKUP(B11,neracalajur,18,0) -> 0
B12: ='Worksheet (6)'!B18 -> 10010 | C12: =VLOOKUP(B12,neracalajur,2,0) -> Asuransi Dibayar Dimuka | D12: =VLOOKUP(B12,neracalajur,3,0) -> Db | E12: =VLOOKUP(B12,neracalajur,17,0) -> 0 | F12: =VLOOKUP(B12,neracalajur,18,0) -> 0
B13: ='Worksheet (6)'!B19 -> 10011 | C13: =VLOOKUP(B13,neracalajur,2,0) -> 0 | D13: =VLOOKUP(B13,neracalajur,3,0) -> Db | E13: =VLOOKUP(B13,neracalajur,17,0) -> 0 | F13: =VLOOKUP(B13,neracalajur,18,0) -> 0
... B23: ='Worksheet (6)'!B29 -> 11000 | C23: =VLOOKUP(B23,neracalajur,2,0) -> Harta tetap | D23: =VLOOKUP(B23,neracalajur,3,0) -> Db | E23: =VLOOKUP(B23,neracalajur,17,0) -> 0 | F23: =VLOOKUP(B23,neracalajur,18,0) -> 0
G24: =SUM(E2:E23) -> 590000 | H24: =SUM(F2:F23) -> 0
G25: =G24-H24 -> 590000
B26: ='Worksheet (6)'!B30 -> 11001 | C26: =VLOOKUP(B26,neracalajur,2,0) -> Peralatan Kantor | D26: =VLOOKUP(B26,neracalajur,3,0) -> Db | E26: =VLOOKUP(B26,neracalajur,17,0) -> 0 | F26: =VLOOKUP(B26,neracalajur,18,0) -> 0
B27: ='Worksheet (6)'!B31 -> 11002 | C27: =VLOOKUP(B27,neracalajur,2,0) -> Akumulasi Penyusutan Peralatan Kantor | D27: =VLOOKUP(B27,neracalajur,3,0) -> Kr | E27: =VLOOKUP(B27,neracalajur,17,0) -> 0 | F27: =VLOOKUP(B27,neracalajur,18,0) -> 0
B28: ='Worksheet (6)'!B32 -> 11003 | C28: =VLOOKUP(B28,neracalajur,2,0) -> Kendaraan | D28: =VLOOKUP(B28,neracalajur,3,0) -> Db | E28: =VLOOKUP(B28,neracalajur,17,0) -> 0 | F28: =VLOOKUP(B28,neracalajur,18,0) -> 0
B29: ='Worksheet (6)'!B33 -> 11004 | C29: =VLOOKUP(B29,neracalajur,2,0) -> Akumulasi Penyusutan Peralatanan Kendaraan | D29: =VLOOKUP(B29,neracalajur,3,0) -> Kr | E29: =VLOOKUP(B29,neracalajur,17,0) -> 0 | F29: =VLOOKUP(B29,neracalajur,18,0) -> 0
B30: ='Worksheet (6)'!B34 -> 11005 | C30: =VLOOKUP(B30,neracalajur,2,0) -> Gedung | D30: =VLOOKUP(B30,neracalajur,3,0) -> Db | E30: =VLOOKUP(B30,neracalajur,17,0) -> 0 | F30: =VLOOKUP(B30,neracalajur,18,0) -> 0
B31: ='Worksheet (6)'!B35 -> 11006 | C31: =VLOOKUP(B31,neracalajur,2,0) -> Akumulasi Penyusutan Gedung | D31: =VLOOKUP(B31,neracalajur,3,0) -> Kr | E31: =VLOOKUP(B31,neracalajur,17,0) -> 0 | F31: =VLOOKUP(B31,neracalajur,18,0) -> 0
B32: ='Worksheet (6)'!B36 -> 11007 | C32: =VLOOKUP(B32,neracalajur,2,0) -> Mesin | D32: =VLOOKUP(B32,neracalajur,3,0) -> Db | E32: =VLOOKUP(B32,neracalajur,17,0) -> 0 | F32: =VLOOKUP(B32,neracalajur,18,0) -> 0
B33: ='Worksheet (6)'!B37 -> 11008 | C33: =VLOOKUP(B33,neracalajur,2,0) -> Akumulasi Penyusutan Mesin | D33: =VLOOKUP(B33,neracalajur,3,0) -> Kr | E33: =VLOOKUP(B33,neracalajur,17,0) -> 0 | F33: =VLOOKUP(B33,neracalajur,18,0) -> 0
B34: ='Worksheet (6)'!B38 -> 11009 | C34: =VLOOKUP(B34,neracalajur,2,0) -> Peralatan Toko | D34: =VLOOKUP(B34,neracalajur,3,0) -> Db | E34: =VLOOKUP(B34,neracalajur,17,0) -> 0 | F34: =VLOOKUP(B34,neracalajur,18,0) -> 0
B35: ='Worksheet (6)'!B39 -> 11010 | C35: =VLOOKUP(B35,neracalajur,2,0) -> Akumulasi Penyusutan Peralatan Toko | D35: =VLOOKUP(B35,neracalajur,3,0) -> Kr | E35: =VLOOKUP(B35,neracalajur,17,0) -> 0 | F35: =VLOOKUP(B35,neracalajur,18,0) -> 0
B36: ='Worksheet (6)'!B40 -> 11011 | C36: =VLOOKUP(B36,neracalajur,2,0) -> Tanah | D36: =VLOOKUP(B36,neracalajur,3,0) -> Db | E36: =VLOOKUP(B36,neracalajur,17,0) -> 0 | F36: =VLOOKUP(B36,neracalajur,18,0) -> 0
B37: ='Worksheet (6)'!B41 -> 11012 | C37: =VLOOKUP(B37,neracalajur,2,0) -> 0 | D37: =VLOOKUP(B37,neracalajur,3,0) -> Db | E37: =VLOOKUP(B37,neracalajur,17,0) -> 0 | F37: =VLOOKUP(B37,neracalajur,18,0) -> 0
B38: ='Worksheet (6)'!B42 -> 11013 | C38: =VLOOKUP(B38,neracalajur,2,0) -> 0 | D38: =VLOOKUP(B38,neracalajur,3,0) -> Db | E38: =VLOOKUP(B38,neracalajur,17,0) -> 0 | F38: =VLOOKUP(B38,neracalajur,18,0) -> 0
G39: =SUM(E26:E38) -> 0 | H39: =SUM(F26:F38) -> 0
H40: =H39-G39 -> 0
B41: ='Worksheet (6)'!B43 -> 11014 | C41: =VLOOKUP(B41,neracalajur,2,0) -> 0 | D41: =VLOOKUP(B41,neracalajur,3,0) -> Db | E41: =VLOOKUP(B41,neracalajur,17,0) -> 0 | F41: ='Changes Capital Statement (9)'!G14 -> 590000
G42: =SUM(E41:E41) -> 0 | H42: =SUM(F41:F41) -> 590000
H43: =H42-G42 -> 590000
H44: =H43+H40 -> 590000

Sheet Financial Position statemen(11)
B2: ='Worksheet (6)'!B2:S2 -> CV Max Picture
B3: Laporan Posis Keuangan
B4: ='Worksheet (6)'!B4:S4 -> Periode Desember 2021
B5: ='Worksheet (6)'!B5:S5 -> ~ Dilarang keras merubah (Apapun) yang bukan menjadi kepentingan Anda ! ~
B6: Kode | C6: Keterangan | D6: SN | E6: Debet | F6: Kredit | G6: Saldo
A7: =IF(C7=0,0,1) -> 1 | B7: ='Worksheet (6)'!B8 -> 10000 | C7: =VLOOKUP(B7,neracalajur,2,0) -> Harta Lancar | D7: =VLOOKUP(B7,neracalajur,3,0) -> Db | E7: =VLOOKUP(B7,neracalajur,17,0) -> 0 | F7: =VLOOKUP(B7,neracalajur,18,0) -> 0 | G7: =IF(D7="Kr",F7-E7,E7-F7) -> 0
A8: =IF(C8=0,0,1) -> 1 | B8: ='Worksheet (6)'!B9 -> 10001 | C8: =VLOOKUP(B8,neracalajur,2,0) -> Kas | D8: =VLOOKUP(B8,neracalajur,3,0) -> Db | E8: =VLOOKUP(B8,neracalajur,17,0) -> 80000 | F8: =VLOOKUP(B8,neracalajur,18,0) -> 0 | G8: =IF(D8="Kr",F8-E8,E8-F8) -> 80000
A9: =IF(C9=0,0,1) -> 1 | B9: ='Worksheet (6)'!B10 -> 10002 | C9: =VLOOKUP(B9,neracalajur,2,0) -> Persediaan Barang Dagang | D9: =VLOOKUP(B9,neracalajur,3,0) -> Db | E9: =VLOOKUP(B9,neracalajur,17,0) -> 0 | F9: =VLOOKUP(B9,neracalajur,18,0) -> 0 | G9: =IF(D9="Kr",F9-E9,E9-F9) -> 0
A10: =IF(C10=0,0,1) -> 1 | B10: ='Worksheet (6)'!B11 -> 10003 | C10: =VLOOKUP(B10,neracalajur,2,0) -> Piutang Usaha | D10: =VLOOKUP(B10,neracalajur,3,0) -> Db | E10: =VLOOKUP(B10,neracalajur,17,0) -> 500000 | F10: =VLOOKUP(B10,neracalajur,18,0) -> 0 | G10: =IF(D10="Kr",F10-E10,E10-F10) -> 500000
A11: =IF(C11=0,0,1) -> 1 | B11: ='Worksheet (6)'!B12 -> 10004 | C11: =VLOOKUP(B11,neracalajur,2,0) -> Piutang Pendapatan | D11: =VLOOKUP(B11,neracalajur,3,0) -> Db | E11: =VLOOKUP(B11,neracalajur,17,0) -> 0 | F11: =VLOOKUP(B11,neracalajur,18,0) -> 0 | G11: =IF(D11="Kr",F11-E11,E11-F11) -> 0
A12: =IF(C12=0,0,1) -> 1 | B12: ='Worksheet (6)'!B13 -> 10005 | C12: =VLOOKUP(B12,neracalajur,2,0) -> Wesel Tagih | D12: =VLOOKUP(B12,neracalajur,3,0) -> Db | E12: =VLOOKUP(B12,neracalajur,17,0) -> 0 | F12: =VLOOKUP(B12,neracalajur,18,0) -> 0 | G12: =IF(D12="Kr",F12-E12,E12-F12) -> 0
A13: =IF(C13=0,0,1) -> 1 | B13: ='Worksheet (6)'!B14 -> 10006 | C13: =VLOOKUP(B13,neracalajur,2,0) -> Perlengkapan Kantor | D13: =VLOOKUP(B13,neracalajur,3,0) -> Db | E13: =VLOOKUP(B13,neracalajur,17,0) -> 10000 | F13: =VLOOKUP(B13,neracalajur,18,0) -> 0 | G13: =IF(D13="Kr",F13-E13,E13-F13) -> 10000
A14: =IF(C14=0,0,1) -> 1 | B14: ='Worksheet (6)'!B15 -> 10007 | C14: =VLOOKUP(B14,neracalajur,2,0) -> Perlengkapan Toko | D14: =VLOOKUP(B14,neracalajur,3,0) -> Db | E14: =VLOOKUP(B14,neracalajur,17,0) -> 0 | F14: =VLOOKUP(B14,neracalajur,18,0) -> 0 | G14: =IF(D14="Kr",F14-E14,E14-F14) -> 0
A15: =IF(C15=0,0,1) -> 1 | B15: ='Worksheet (6)'!B16 -> 10008 | C15: =VLOOKUP(B15,neracalajur,2,0) -> Iklan Dibayar Dimuka | D15: =VLOOKUP(B15,neracalajur,3,0) -> Db | E15: =VLOOKUP(B15,neracalajur,17,0) -> 0 | F15: =VLOOKUP(B15,neracalajur,18,0) -> 0 | G15: =IF(D15="Kr",F15-E15,E15-F15) -> 0
A16: =IF(C16=0,0,1) -> 1 | B16: ='Worksheet (6)'!B17 -> 10009 | C16: =VLOOKUP(B16,neracalajur,2,0) -> Sewa Dibayar Dimuka | D16: =VLOOKUP(B16,neracalajur,3,0) -> Db | E16: =VLOOKUP(B16,neracalajur,17,0) -> 0 | F16: =VLOOKUP(B16,neracalajur,18,0) -> 0 | G16: =IF(D16="Kr",F16-E16,E16-F16) -> 0
A17: =IF(C17=0,0,1) -> 1 | B17: ='Worksheet (6)'!B18 -> 10010 | C17: =VLOOKUP(B17,neracalajur,2,0) -> Asuransi Dibayar Dimuka | D17: =VLOOKUP(B17,neracalajur,3,0) -> Db | E17: =VLOOKUP(B17,neracalajur,17,0) -> 0 | F17: =VLOOKUP(B17,neracalajur,18,0) -> 0 | G17: =IF(D17="Kr",F17-E17,E17-F17) -> 0
A18: =IF(C18=0,0,1) -> 0 | B18: ='Worksheet (6)'!B19 -> 10011 | C18: =VLOOKUP(B18,neracalajur,2,0) -> 0 | D18: =VLOOKUP(B18,neracalajur,3,0) -> Db | E18: =VLOOKUP(B18,neracalajur,17,0) -> 0 | F18: =VLOOKUP(B18,neracalajur,18,0) -> 0 | G18: =IF(D18="Kr",F18-E18,E18-F18) -> 0
... A27: =IF(C27=0,0,1) -> 0 | B27: ='Worksheet (6)'!B28 -> 10020 | C27: =VLOOKUP(B27,neracalajur,2,0) -> 0 | D27: =VLOOKUP(B27,neracalajur,3,0) -> Db | E27: =VLOOKUP(B27,neracalajur,17,0) -> 0 | F27: =VLOOKUP(B27,neracalajur,18,0) -> 0 | G27: =IF(D27="Kr",F27-E27,E27-F27) -> 0
A28: =IF(C28=0,0,1) -> 1 | C28: Total Harta lancar | D28: Ʃ | E28: =SUM(E7:E27) -> 590000 | F28: =SUM(F7:F27) -> 0 | G28: =IFERROR(IF(E28>F28,E28-F28,F28-E28),0) -> 590000
A29: =IF(C29=0,0,1) -> 1 | B29: ='Worksheet (6)'!B29 -> 11000 | C29: =VLOOKUP(B29,neracalajur,2,0) -> Harta tetap | D29: =VLOOKUP(B29,neracalajur,3,0) -> Db | E29: =VLOOKUP(B29,neracalajur,17,0) -> 0 | F29: =VLOOKUP(B29,neracalajur,18,0) -> 0 | G29: =IF(D29="Kr",F29-E29,E29-F29) -> 0
A30: =IF(C30=0,0,1) -> 1 | B30: ='Worksheet (6)'!B30 -> 11001 | C30: =VLOOKUP(B30,neracalajur,2,0) -> Peralatan Kantor | D30: =VLOOKUP(B30,neracalajur,3,0) -> Db | E30: =VLOOKUP(B30,neracalajur,17,0) -> 0 | F30: =VLOOKUP(B30,neracalajur,18,0) -> 0 | G30: =IF(D30="Kr",F30-E30,E30-F30) -> 0
A31: =IF(C31=0,0,1) -> 1 | B31: ='Worksheet (6)'!B31 -> 11002 | C31: =VLOOKUP(B31,neracalajur,2,0) -> Akumulasi Penyusutan Peralatan Kantor | D31: =VLOOKUP(B31,neracalajur,3,0) -> Kr | E31: =VLOOKUP(B31,neracalajur,17,0) -> 0 | F31: =VLOOKUP(B31,neracalajur,18,0) -> 0 | G31: =IF(D31="Kr",F31-E31,E31-F31) -> 0
A32: =IF(C32=0,0,1) -> 1 | B32: ='Worksheet (6)'!B32 -> 11003 | C32: =VLOOKUP(B32,neracalajur,2,0) -> Kendaraan | D32: =VLOOKUP(B32,neracalajur,3,0) -> Db | E32: =VLOOKUP(B32,neracalajur,17,0) -> 0 | F32: =VLOOKUP(B32,neracalajur,18,0) -> 0 | G32: =IF(D32="Kr",F32-E32,E32-F32) -> 0
A33: =IF(C33=0,0,1) -> 1 | B33: ='Worksheet (6)'!B33 -> 11004 | C33: =VLOOKUP(B33,neracalajur,2,0) -> Akumulasi Penyusutan Peralatanan Kendaraan | D33: =VLOOKUP(B33,neracalajur,3,0) -> Kr | E33: =VLOOKUP(B33,neracalajur,17,0) -> 0 | F33: =VLOOKUP(B33,neracalajur,18,0) -> 0 | G33: =IF(D33="Kr",F33-E33,E33-F33) -> 0
A34: =IF(C34=0,0,1) -> 1 | B34: ='Worksheet (6)'!B34 -> 11005 | C34: =VLOOKUP(B34,neracalajur,2,0) -> Gedung | D34: =VLOOKUP(B34,neracalajur,3,0) -> Db | E34: =VLOOKUP(B34,neracalajur,17,0) -> 0 | F34: =VLOOKUP(B34,neracalajur,18,0) -> 0 | G34: =IF(D34="Kr",F34-E34,E34-F34) -> 0
A35: =IF(C35=0,0,1) -> 1 | B35: ='Worksheet (6)'!B35 -> 11006 | C35: =VLOOKUP(B35,neracalajur,2,0) -> Akumulasi Penyusutan Gedung | D35: =VLOOKUP(B35,neracalajur,3,0) -> Kr | E35: =VLOOKUP(B35,neracalajur,17,0) -> 0 | F35: =VLOOKUP(B35,neracalajur,18,0) -> 0 | G35: =IF(D35="Kr",F35-E35,E35-F35) -> 0
A36: =IF(C36=0,0,1) -> 1 | B36: ='Worksheet (6)'!B36 -> 11007 | C36: =VLOOKUP(B36,neracalajur,2,0) -> Mesin | D36: =VLOOKUP(B36,neracalajur,3,0) -> Db | E36: =VLOOKUP(B36,neracalajur,17,0) -> 0 | F36: =VLOOKUP(B36,neracalajur,18,0) -> 0 | G36: =IF(D36="Kr",F36-E36,E36-F36) -> 0
A37: =IF(C37=0,0,1) -> 1 | B37: ='Worksheet (6)'!B37 -> 11008 | C37: =VLOOKUP(B37,neracalajur,2,0) -> Akumulasi Penyusutan Mesin | D37: =VLOOKUP(B37,neracalajur,3,0) -> Kr | E37: =VLOOKUP(B37,neracalajur,17,0) -> 0 | F37: =VLOOKUP(B37,neracalajur,18,0) -> 0 | G37: =IF(D37="Kr",F37-E37,E37-F37) -> 0
